Workbook
Name meta_coordinador: Asistencia!$G$2
Name meta_nomina: Asistencia!$D$2
Name meta_semana: Asistencia!$B$2

Sheet Instrucciones
B1: PROCLEAN · ASISTENCIA NÓMINA MIÉRCOLES v3 · CAPTURA POR CLIENTE / TURNO
B3: 1. CLAVES DE ASISTENCIA DIARIA
B4: CLAVE | C4: SIGNIFICADO | D4: CUÁNDO USAR | F4: COLOR
B5: A | C5: Asistencia | D5: El empleado trabajó su turno normal | F5: Verde
B6: D | C6: Descanso programado | D6: Día de descanso según horario | F6: Azul
B7: F | C7: Falta | D7: Ausencia injustificada | F7: Rojo
B8: V | C8: Vacaciones | D8: Días de vacaciones disfrutadas | F8: Amarillo
B9: I | C9: Incapacidad IMSS | D9: Baja médica con folio IMSS | F9: Gris
B10: PSS | C10: Permiso sin goce de sueldo | D10: Permiso autorizado sin pago | F10: Rojo
B11: PCS | C11: Permiso con goce de sueldo | D11: Permiso autorizado con pago | F11: Rojo
B12: NI | C12: Nuevo ingreso | D12: Primera semana del empleado nuevo | F12: Gris
B13: B | C13: Baja | D13: El empleado causó baja definitiva | F13: Rojo
B14: R | C14: Retardo | D14: Llegó tarde pero trabajó | F14: Amarillo
B15: S | C15: Suspensión | D15: Suspensión disciplinaria | F15: Rojo
... B19: OT | C19: Otro / Revisar | D19: Caso especial – explicar en Observaciones | F19: Morado
B21: 2. COLUMNAS DE INCIDENCIAS OPERATIVAS
B22: COLUMNA | C22: QUÉ CAPTURA | D22: TIPO DE DATO | E22: EJEMPLO | F22: NOTAS
B23: HE | C23: Horas extra trabajadas | D23: Número ≥ 0 | E23: 3 / 4.5 / 8 | F23: No capturar monto
B24: TURNOS EXTRA NORMALES | C24: Horas trabajadas en turno extra | D24: Número ≥ 0 | E24: 8 / 16 | F24: Si trabajó turno completo = 8hrs
B25: DÍAS CUBIERTOS NORMALES | C25: Días extra cubiertos | D25: Número ≥ 0 | E25: 1 / 2 | F25: Para extras que se miden por día
B26: FESTIVO LABORADO | C26: Días festivos trabajados | D26: Número ≥ 0 | E26: 1 | F26: También marcar FL en el día
B27: DOMINGO LABORADO | C27: Domingos trabajados | D27: Número ≥ 0 | E27: 1 | F27: También marcar DL en el día
B28: VACACIONES LABORADAS | C28: Vacaciones que se piden como laboradas | D28: Número ≥ 0 | E28: 1 / 2 | F28: NO para vacaciones disfrutadas (esas van como V)
B29: PRIMA VACACIONAL | C29: Solicitud de prima vacacional | D29: N/A o SOLICITA | E29: SOLICITA | F29: N/A por default. Nómina verificará en la app.
B30: BONO | C30: Bono o apoyo especial | D30: Número o texto | E30: 300 / 'revisar bono' | F30: Monto preliminar sujeto a revisión de Nómina
B31: DEDUCCIONES | C31: Descuentos o deducciones | D31: Número o texto | E31: 150 / 'préstamo' | F31: No calcular en Excel. Nómina valida en app.
B32: OBSERVACIONES | C32: Notas o aclaraciones libres | D32: Texto | E32: 'Falta sin aviso' | F32: Obligatorio si usa clave OT
B34: 3. INSTRUCCIONES DE LLENADO
B35: REGLA DE ORO: Este archivo solo captura asistencia e incidencias operativas. NUNCA capturar importes de nómina.
B36: Días de la semana | C36: Captura UNA clave por día. Usa solo las claves del catálogo. Si el caso es raro, usa OT y explica en Observaciones.
B37: Incidencias | C37: Las columnas de incidencias registran cantidades o datos adicionales. No capturan sueldo ni cálculo.
B38: No modificar | C38: No cambiar encabezados de columnas. No inventar claves. No agregar hojas.
B39: Flujo del archivo | C39: 1) Descarga desde ProClean-App 2) Llena asistencia e incidencias 3) Sube a ProClean-App 4) Nómina revisa y aprueba en web.
B40: Caso no contemplado | C40: Usa OT en el día y escribe la situación en la columna OBSERVACIONES para que Nómina la revise.
B42: 4. EJEMPLOS PRÁCTICOS DE LLENADO
B43: Ej 1 – Semana normal | C43: Días: A, A, D, A, A, A, A | Incidencias: todas vacías
B44: Ej 2 – Falta | C44: Día correspondiente: F | Observaciones: opcional
B45: Ej 3 – Permiso sin goce | C45: Día: PSS
B46: Ej 4 – Permiso con goce | C46: Día: PCS
B47: Ej 5 – Vacaciones | C47: Días correspondientes: V, V, V…
...

Sheet Asistencia
A1: PROCLEAN
A2: SEMANA: | B2: NOMINA: | C2: MIÉRCOLES | E2: COORDINADOR:
A4: CLIENTE: ARMIDA
A5: NOMBRE DE EMPLEADO | B5: CLIENTE | C5: PLANTA | D5: TURNO | E5: PUESTO | F5: V1 | G5: S2 | H5: D3 | I5: L4 | J5: M5 | K5: M6 | L5: J7 | M5: HORAS EXTRA | N5: HORAS EXTRA NORMALES | O5: DÍAS CUBIERTOS NORMALES | P5: BONO | Q5: OBSERVACIONES
B6: ARMIDA
B7: ARMIDA
B8: ARMIDA
B9: ARMIDA
B10: ARMIDA
B11: ARMIDA
B12: ARMIDA
B13: ARMIDA
B14: ARMIDA
B15: ARMIDA
B16: ARMIDA
B17: ARMIDA
... B45: ARMIDA
A46: CLIENTE: AURIGA
A47: NOMBRE DE EMPLEADO | B47: CLIENTE | C47: PLANTA | D47: TURNO | E47: PUESTO | F47: V1 | G47: S2 | H47: D3 | I47: L4 | J47: M5 | K47: M6 | L47: J7 | M47: HORAS EXTRA | N47: HORAS EXTRA NORMALES | O47: DÍAS CUBIERTOS NORMALES | P47: BONO | Q47: OBSERVACIONES
B48: AURIGA
B49: AURIGA
B50: AURIGA
B51: AURIGA
B52: AURIGA
B53: AURIGA
B54: AURIGA
B55: AURIGA
B56: AURIGA
B57: AURIGA
B58: AURIGA
B59: AURIGA
... B87: AURIGA
A88: CLIENTE: AURORA
A89: NOMBRE DE EMPLEADO | B89: CLIENTE | C89: PLANTA | D89: TURNO | E89: PUESTO | F89: V1 | G89: S2 | H89: D3 | I89: L4 | J89: M5 | K89: M6 | L89: J7 | M89: HORAS EXTRA | N89: HORAS EXTRA NORMALES | O89: DÍAS CUBIERTOS NORMALES | P89: BONO | Q89: OBSERVACIONES
B90: AURORA
B91: AURORA
B92: AURORA
B93: AURORA
B94: AURORA
B95: AURORA
...

Sheet Compilado
A1: PROCLEAN · COMPILADO POR TRABAJADOR · NÓMINA MIÉRCOLES
A2: SEMANA: | B2: NOMINA: | E2: COORDINADOR:
A4: NOMBRE COMPLETO | B4: PUESTO | C4: BANCO | D4: CUENTA | E4: CLIENTES / TURNOS DONDE LABORÓ | F4: V1 | G4: S2 | H4: D3 | I4: L4 | J4: M5 | K4: M6 | L4: J7 | M4: DÍAS ÚNICOS LABORADOS | N4: DÍAS ADICIONALES DETECTADOS | O4: EVENTOS ADICIONALES MISMO DÍA | P4: HORAS EXTRA | Q4: HORAS EXTRA NORMALES | R4: DÍAS CUBIERTOS NORMALES | S4: VACACIONES LABORADAS | T4: PRIMA VACACIONAL | U4: BONO | V4: DEDUCCIONES | W4: OBSERVACIONES | Y4: mRow | Z4: wKey | AA4: key | AB4: nombre | AC4: nrmNom | AD4: puesto | AE4: turno | AF4: cliente | AG4: isFirst | AH4: uID | AI4: w1 | AJ4: w2 | AK4: w3 | AL4: w4 | AM4: w5 | AN4: w6 | AO4: w7 | AP4: wSum | AQ4: fl1 | AR4: fl2 | AS4: fl3 | AT4: fl4 | AU4: fl5 | AV4: fl6 | AW4: fl7 | AX4: flSum | AY4: dl1 | AZ4: dl2 | BA4: dl3 | BB4: dl4 | BC4: dl5 | BD4: dl6 | BE4: dl7 | BF4: dlSum | BG4: HE | BH4: HEN | BI4: DCN | BJ4: Bono | BK4: day1 | BL4: day2 | BM4: day3 | BN4: day4 | BO4: day5 | BP4: day6 | BQ4: day7
A5: =IF(Y5="","",INDEX($AB$5:$AB$323,Y5)) | B5: =IF(Y5="","",INDEX($AD$5:$AD$323,Y5)) | E5: =IF($A5="","",_xlfn.TEXTJOIN(" / ",TRUE(),IF(SUMIFS($AP$5:$AP$323,$AA$5:$AA$323,$Z5,$AF$5:$AF$323,"ARMIDA")>0,IFERROR("ARMIDA-"&INDEX($AE$5:$AE$323,MATCH($Z5&"ARMIDA",$AA$5:$AA$323&$AF$5:$AF$323,0)),"ARMIDA"),""),IF(SUMIFS($AP$5:$AP$323,$AA$5:$AA$323,$Z5,$AF$5:$AF$323,"AURIGA")>0,IFERROR("AURIGA-"&INDEX($AE$5:$AE$323,MATCH($Z5&"AURIGA",$AA$5:$AA$323&$AF$5:$AF$323,0)),"AURIGA"),""),IF(SUMIFS($AP$5:$AP$323,$AA$5:$AA$323,$Z5,$AF$5:$AF$323,"AURORA")>0,IFERROR("AURORA-"&INDEX($AE$5:$AE$323,MATCH($Z5&"AURORA",$AA$5:$AA$323&$AF$5:$AF$323,0)),"AURORA"),""),IF(SUMIFS($AP$5:$AP$323,$AA$5:$AA$323,$Z5,$AF$5:$AF$323,"CITICA")>0,IFERROR("CITICA-"&INDEX($AE$5:$AE$323,MATCH($Z5&"CITICA",$AA$5:$AA$323&$AF$5:$AF$323,0)),"CITICA"),""),IF(SUMIFS($AP$5:$AP$323,$AA$5:$AA$323,$Z5,$AF$5:$AF$323,"GM")>0,IFERROR("GM-"&INDEX($AE$5:$AE$323,MATCH($Z5&"GM",$AA$5:$AA$323&$AF$5:$AF$323,0)),"GM"),""),IF(SUMIFS($AP$5:$AP$323,$AA$5:$AA$323,$Z5,$AF$5:$AF$323,"TORRE BALZAK")>0,IFERROR("TORRE BALZAK-"&INDEX($AE$5:$AE$323,MATCH($Z5&"TORRE BALZAK",$AA$5:$AA$323&$AF$5:$AF$323,0)),"TORRE BALZAK"),""),IF(SUMIFS($AP$5:$AP$323,$AA$5:$AA$323,$Z5,$AF$5:$AF$323,"TORRE OLMA")>0,IFERROR("TORRE OLMA-"&INDEX($AE$5:$AE$323,MATCH($Z5&"TORRE OLMA",$AA$5:$AA$323&$AF$5:$AF$323,0)),"TORRE OLMA"),""),IF(SUMIFS($AP$5:$AP$323,$AA$5:$AA$323,$Z5,$AF$5:$AF$323,"OTROS")>0,IFERROR("OTROS-"&INDEX($AE$5:$AE$323,MATCH($Z5&"OTROS",$AA$5:$AA$323&$AF$5:$AF$323,0)),"OTROS"),""))) | F5: =IF($A5="","",IFERROR(INDEX($BK$5:$BK$323,MATCH($Z5,$AA$5:$AA$323,0)),"-")) | G5: =IF($A5="","",IFERROR(INDEX($BL$5:$BL$323,MATCH($Z5,$AA$5:$AA$323,0)),"-")) | H5: =IF($A5="","",IFERROR(INDEX($BM$5:$BM$323,MATCH($Z5,$AA$5:$AA$323,0)),"-")) | I5: =IF($A5="","",IFERROR(INDEX($BN$5:$BN$323,MATCH($Z5,$AA$5:$AA$323,0)),"-")) | J5: =IF($A5="","",IFERROR(INDEX($BO$5:$BO$323,MATCH($Z5,$AA$5:$AA$323,0)),"-")) | K5: =IF($A5="","",IFERROR(INDEX($BP$5:$BP$323,MATCH($Z5,$AA$5:$AA$323,0)),"-")) | L5: =IF($A5="","",IFERROR(INDEX($BQ$5:$BQ$323,MATCH($Z5,$AA$5:$AA$323,0)),"-")) | M5: =IF($A5="","",(--(SUMIF($AA$5:$AA$323,$Z5,$AI$5:$AI$323)>0))+(--(SUMIF($AA$5:$AA$323,$Z5,$AJ$5:$AJ$323)>0))+(--(SUMIF($AA$5:$AA$323,$Z5,$AK$5:$AK$323)>0))+(--(SUMIF($AA$5:$AA$323,$Z5,$AL$5:$AL$323)>0))+(--(SUMIF($AA$5:$AA$323,$Z5,$AM$5:$AM$323)>0))+(--(SUMIF($AA$5:$AA$323,$Z5,$AN$5:$AN$323)>0))+(--(SUMIF($AA$5:$AA$323,$Z5,$AO$5:$AO$323)>0))) | N5: =IF($A5="","",MAX(0,M5-6)) | O5: =IF($A5="","",SUMIF($AA$5:$AA$323,$Z5,$AP$5:$AP$323)-M5) | P5: =IF($A5="","",SUMIF($AA$5:$AA$323,$Z5,$BG$5:$BG$323)) | Q5: =IF($A5="","",SUMIF($AA$5:$AA$323,$Z5,$BH$5:$BH$323)) | R5: =IF($A5="","",SUMIF($AA$5:$AA$323,$Z5,$BI$5:$BI$323)) | U5: =IF($A5="","",SUMIF($AA$5:$AA$323,$Z5,$BJ$5:$BJ$323)) | W5: =IF($A5="","",_xlfn.TEXTJOIN(" | ",TRUE(),IF(N5>0,"+ de 6 días: revisar adicionales",""),IF(O5>0,"Doble evento mismo día: revisar turno/pago",""),IF(SUMIF($AA$5:$AA$323,$Z5,$AX$5:$AX$323)>((--(SUMIF($AA$5:$AA$323,$Z5,$AQ$5:$AQ$323)>0))+(--(SUMIF($AA$5:$AA$323,$Z5,$AR$5:$AR$323)>0))+(--(SUMIF($AA$5:$AA$323,$Z5,$AS$5:$AS$323)>0))+(--(SUMIF($AA$5:$AA$323,$Z5,$AT$5:$AT$323)>0))+(--(SUMIF($AA$5:$AA$323,$Z5,$AU$5:$AU$323)>0))+(--(SUMIF($AA$5:$AA$323,$Z5,$AV$5:$AV$323)>0))+(--(SUMIF($AA$5:$AA$323,$Z5,$AW$5:$AW$323)>0))),"FL múltiple mismo día: revisar pago festivo",""),IF(SUMIF($AA$5:$AA$323,$Z5,$BF$5:$BF$323)>((--(SUMIF($AA$5:$AA$323,$Z5,$AY$5:$AY$323)>0))+(--(SUMIF($AA$5:$AA$323,$Z5,$AZ$5:$AZ$323)>0))+(--(SUMIF($AA$5:$AA$323,$Z5,$BA$5:$BA$323)>0))+(--(SUMIF($AA$5:$AA$323,$Z5,$BB$5:$BB$323)>0))+(--(SUMIF($AA$5:$AA$323,$Z5,$BC$5:$BC$323)>0))+(--(SUMIF($AA$5:$AA$323,$Z5,$BD$5:$BD$323)>0))+(--(SUMIF($AA$5:$AA$323,$Z5,$BE$5:$BE$323)>0))),"DL múltiple mismo día: revisar pago descanso",""))) | Y5: =IFERROR(MATCH(1,$AH$5:$AH$323,0),"") | Z5: =IF(Y5="","",INDEX($AA$5:$AA$323,Y5)) | AA5: =IF(AC5="","","M:"&AC5) | AB5: =IF(Asistencia!A6="","",Asistencia!A6) | AC5: =IF(Asistencia!A6="","",SUBSTITUTE(SUBSTITUTE(SUBSTITUTE(SUBSTITUTE(SUBSTITUTE(SUBSTITUTE(SUBSTITUTE(UPPER(TRIM(Asistencia!A6)),"Á","A"),"É","E"),"Í","I"),"Ó","O"),"Ú","U"),"Ñ","N")," "," ")) | AD5: =IF(Asistencia!E6="","",Asistencia!E6) | AE5: =IF(Asistencia!D6="","",UPPER(TRIM(Asistencia!D6))) | AF5: ARMIDA | AG5: =IF(AND(AA5<>"",COUNTIF($AA$5:AA5,AA5)=1),1,0) -> 0 | AH5: =IF(AG5=1,SUM($AG$5:AG5),"") | AI5: =IF(OR(EXACT(Asistencia!F6,"A"),EXACT(Asistencia!F6,"R"),EXACT(Asistencia!F6,"DL"),EXACT(Asistencia!F6,"FL"),EXACT(Asistencia!F6,"FE"),EXACT(Asistencia!F6,"PCS"),EXACT(Asistencia!F6,"V")),1,0) -> 0 | AJ5: =IF(OR(EXACT(Asistencia!G6,"A"),EXACT(Asistencia!G6,"R"),EXACT(Asistencia!G6,"DL"),EXACT(Asistencia!G6,"FL"),EXACT(Asistencia!G6,"FE"),EXACT(Asistencia!G6,"PCS"),EXACT(Asistencia!G6,"V")),1,0) -> 0 | AK5: =IF(OR(EXACT(Asistencia!H6,"A"),EXACT(Asistencia!H6,"R"),EXACT(Asistencia!H6,"DL"),EXACT(Asistencia!H6,"FL"),EXACT(Asistencia!H6,"FE"),EXACT(Asistencia!H6,"PCS"),EXACT(Asistencia!H6,"V")),1,0) -> 0 | AL5: =IF(OR(EXACT(Asistencia!I6,"A"),EXACT(Asistencia!I6,"R"),EXACT(Asistencia!I6,"DL"),EXACT(Asistencia!I6,"FL"),EXACT(Asistencia!I6,"FE"),EXACT(Asistencia!I6,"PCS"),EXACT(Asistencia!I6,"V")),1,0) -> 0 | AM5: =IF(OR(EXACT(Asistencia!J6,"A"),EXACT(Asistencia!J6,"R"),EXACT(Asistencia!J6,"DL"),EXACT(Asistencia!J6,"FL"),EXACT(Asistencia!J6,"FE"),EXACT(Asistencia!J6,"PCS"),EXACT(Asistencia!J6,"V")),1,0) -> 0 | AN5: =IF(OR(EXACT(Asistencia!K6,"A"),EXACT(Asistencia!K6,"R"),EXACT(Asistencia!K6,"DL"),EXACT(Asistencia!K6,"FL"),EXACT(Asistencia!K6,"FE"),EXACT(Asistencia!K6,"PCS"),EXACT(Asistencia!K6,"V")),1,0) -> 0 | AO5: =IF(OR(EXACT(Asistencia!L6,"A"),EXACT(Asistencia!L6,"R"),EXACT(Asistencia!L6,"DL"),EXACT(Asistencia!L6,"FL"),EXACT(Asistencia!L6,"FE"),EXACT(Asistencia!L6,"PCS"),EXACT(Asistencia!L6,"V")),1,0) -> 0 | AP5: =SUM(AI5:AO5) -> 0 | AQ5: =IF(EXACT(Asistencia!F6,"FL"),1,0) -> 0 | AR5: =IF(EXACT(Asistencia!G6,"FL"),1,0) -> 0 | AS5: =IF(EXACT(Asistencia!H6,"FL"),1,0) -> 0 | AT5: =IF(EXACT(Asistencia!I6,"FL"),1,0) -> 0 | AU5: =IF(EXACT(Asistencia!J6,"FL"),1,0) -> 0 | AV5: =IF(EXACT(Asistencia!K6,"FL"),1,0) -> 0 | AW5: =IF(EXACT(Asistencia!L6,"FL"),1,0) -> 0 | AX5: =SUM(AQ5:AW5) -> 0 | AY5: =IF(EXACT(Asistencia!F6,"DL"),1,0) -> 0 | AZ5: =IF(EXACT(Asistencia!G6,"DL"),1,0) -> 0 | BA5: =IF(EXACT(Asistencia!H6,"DL"),1,0) -> 0 | BB5: =IF(EXACT(Asistencia!I6,"DL"),1,0) -> 0 | BC5: =IF(EXACT(Asistencia!J6,"DL"),1,0) -> 0 | BD5: =IF(EXACT(Asistencia!K6,"DL"),1,0) -> 0 | BE5: =IF(EXACT(Asistencia!L6,"DL"),1,0) -> 0 | BF5: =SUM(AY5:BE5) -> 0 | BG5: =IF(ISNUMBER(Asistencia!M6),Asistencia!M6,0) -> 0 | BH5: =IF(ISNUMBER(Asistencia!N6),Asistencia!N6,0) -> 0 | BI5: =IF(ISNUMBER(Asistencia!O6),Asistencia!O6,0) -> 0 | BJ5: =IF(ISNUMBER(Asistencia!P6),Asistencia!P6,0) -> 0 | BK5: =IF(Asistencia!F6="","",Asistencia!F6) | BL5: =IF(Asistencia!G6="","",Asistencia!G6) | BM5: =IF(Asistencia!H6="","",Asistencia!H6) | BN5: =IF(Asistencia!I6="","",Asistencia!I6) | BO5: =IF(Asistencia!J6="","",Asistencia!J6) | BP5: =IF(Asistencia!K6="","",Asistencia!K6) | BQ5: =IF(Asistencia!L6="","",Asistencia!L6)
A6: =IF(Y6="","",INDEX($AB$5:$AB$323,Y6)) | B6: =IF(Y6="","",INDEX($AD$5:$AD$323,Y6)) | E6: =IF($A6="","",_xlfn.TEXTJOIN(" / ",TRUE(),IF(SUMIFS($AP$5:$AP$323,$AA$5:$AA$323,$Z6,$AF$5:$AF$323,"ARMIDA")>0,IFERROR("ARMIDA-"&INDEX($AE$5:$AE$323,MATCH($Z6&"ARMIDA",$AA$5:$AA$323&$AF$5:$AF$323,0)),"ARMIDA"),""),IF(SUMIFS($AP$5:$AP$323,$AA$5:$AA$323,$Z6,$AF$5:$AF$323,"AURIGA")>0,IFERROR("AURIGA-"&INDEX($AE$5:$AE$323,MATCH($Z6&"AURIGA",$AA$5:$AA$323&$AF$5:$AF$323,0)),"AURIGA"),""),IF(SUMIFS($AP$5:$AP$323,$AA$5:$AA$323,$Z6,$AF$5:$AF$323,"AURORA")>0,IFERROR("AURORA-"&INDEX($AE$5:$AE$323,MATCH($Z6&"AURORA",$AA$5:$AA$323&$AF$5:$AF$323,0)),"AURORA"),""),IF(SUMIFS($AP$5:$AP$323,$AA$5:$AA$323,$Z6,$AF$5:$AF$323,"CITICA")>0,IFERROR("CITICA-"&INDEX($AE$5:$AE$323,MATCH($Z6&"CITICA",$AA$5:$AA$323&$AF$5:$AF$323,0)),"CITICA"),""),IF(SUMIFS($AP$5:$AP$323,$AA$5:$AA$323,$Z6,$AF$5:$AF$323,"GM")>0,IFERROR("GM-"&INDEX($AE$5:$AE$323,MATCH($Z6&"GM",$AA$5:$AA$323&$AF$5:$AF$323,0)),"GM"),""),IF(SUMIFS($AP$5:$AP$323,$AA$5:$AA$323,$Z6,$AF$5:$AF$323,"TORRE BALZAK")>0,IFERROR("TORRE BALZAK-"&INDEX($AE$5:$AE$323,MATCH($Z6&"TORRE BALZAK",$AA$5:$AA$323&$AF$5:$AF$323,0)),"TORRE BALZAK"),""),IF(SUMIFS($AP$5:$AP$323,$AA$5:$AA$323,$Z6,$AF$5:$AF$323,"TORRE OLMA")>0,IFERROR("TORRE OLMA-"&INDEX($AE$5:$AE$323,MATCH($Z6&"TORRE OLMA",$AA$5:$AA$323&$AF$5:$AF$323,0)),"TORRE OLMA"),""),IF(SUMIFS($AP$5:$AP$323,$AA$5:$AA$323,$Z6,$AF$5:$AF$323,"OTROS")>0,IFERROR("OTROS-"&INDEX($AE$5:$AE$323,MATCH($Z6&"OTROS",$AA$5:$AA$323&$AF$5:$AF$323,0)),"OTROS"),""))) | F6: =IF($A6="","",IFERROR(INDEX($BK$5:$BK$323,MATCH($Z6,$AA$5:$AA$323,0)),"-")) | G6: =IF($A6="","",IFERROR(INDEX($BL$5:$BL$323,MATCH($Z6,$AA$5:$AA$323,0)),"-")) | H6: =IF($A6="","",IFERROR(INDEX($BM$5:$BM$323,MATCH($Z6,$AA$5:$AA$323,0)),"-")) | I6: =IF($A6="","",IFERROR(INDEX($BN$5:$BN$323,MATCH($Z6,$AA$5:$AA$323,0)),"-")) | J6: =IF($A6="","",IFERROR(INDEX($BO$5:$BO$323,MATCH($Z6,$AA$5:$AA$323,0)),"-")) | K6: =IF($A6="","",IFERROR(INDEX($BP$5:$BP$323,MATCH($Z6,$AA$5:$AA$323,0)),"-")) | L6: =IF($A6="","",IFERROR(INDEX($BQ$5:$BQ$323,MATCH($Z6,$AA$5:$AA$323,0)),"-")) | M6: =IF($A6="","",(--(SUMIF($AA$5:$AA$323,$Z6,$AI$5:$AI$323)>0))+(--(SUMIF($AA$5:$AA$323,$Z6,$AJ$5:$AJ$323)>0))+(--(SUMIF($AA$5:$AA$323,$Z6,$AK$5:$AK$323)>0))+(--(SUMIF($AA$5:$AA$323,$Z6,$AL$5:$AL$323)>0))+(--(SUMIF($AA$5:$AA$323,$Z6,$AM$5:$AM$323)>0))+(--(SUMIF($AA$5:$AA$323,$Z6,$AN$5:$AN$323)>0))+(--(SUMIF($AA$5:$AA$323,$Z6,$AO$5:$AO$323)>0))) | N6: =IF($A6="","",MAX(0,M6-6)) | O6: =IF($A6="","",SUMIF($AA$5:$AA$323,$Z6,$AP$5:$AP$323)-M6) | P6: =IF($A6="","",SUMIF($AA$5:$AA$323,$Z6,$BG$5:$BG$323)) | Q6: =IF($A6="","",SUMIF($AA$5:$AA$323,$Z6,$BH$5:$BH$323)) | R6: =IF($A6="","",SUMIF($AA$5:$AA$323,$Z6,$BI$5:$BI$323)) | U6: =IF($A6="","",SUMIF($AA$5:$AA$323,$Z6,$BJ$5:$BJ$323)) | W6: =IF($A6="","",_xlfn.TEXTJOIN(" | ",TRUE(),IF(N6>0,"+ de 6 días: revisar adicionales",""),IF(O6>0,"Doble evento mismo día: revisar turno/pago",""),IF(SUMIF($AA$5:$AA$323,$Z6,$AX$5:$AX$323)>((--(SUMIF($AA$5:$AA$323,$Z6,$AQ$5:$AQ$323)>0))+(--(SUMIF($AA$5:$AA$323,$Z6,$AR$5:$AR$323)>0))+(--(SUMIF($AA$5:$AA$323,$Z6,$AS$5:$AS$323)>0))+(--(SUMIF($AA$5:$AA$323,$Z6,$AT$5:$AT$323)>0))+(--(SUMIF($AA$5:$AA$323,$Z6,$AU$5:$AU$323)>0))+(--(SUMIF($AA$5:$AA$323,$Z6,$AV$5:$AV$323)>0))+(--(SUMIF($AA$5:$AA$323,$Z6,$AW$5:$AW$323)>0))),"FL múltiple mismo día: revisar pago festivo",""),IF(SUMIF($AA$5:$AA$323,$Z6,$BF$5:$BF$323)>((--(SUMIF($AA$5:$AA$323,$Z6,$AY$5:$AY$323)>0))+(--(SUMIF($AA$5:$AA$323,$Z6,$AZ$5:$AZ$323)>0))+(--(SUMIF($AA$5:$AA$323,$Z6,$BA$5:$BA$323)>0))+(--(SUMIF($AA$5:$AA$323,$Z6,$BB$5:$BB$323)>0))+(--(SUMIF($AA$5:$AA$323,$Z6,$BC$5:$BC$323)>0))+(--(SUMIF($AA$5:$AA$323,$Z6,$BD$5:$BD$323)>0))+(--(SUMIF($AA$5:$AA$323,$Z6,$BE$5:$BE$323)>0))),"DL múltiple mismo día: revisar pago descanso",""))) | Y6: =IFERROR(MATCH(2,$AH$5:$AH$323,0),"") | Z6: =IF(Y6="","",INDEX($AA$5:$AA$323,Y6)) | AA6: =IF(AC6="","","M:"&AC6) | AB6: =IF(Asistencia!A7="","",Asistencia!A7) | AC6: =IF(Asistencia!A7="","",SUBSTITUTE(SUBSTITUTE(SUBSTITUTE(SUBSTITUTE(SUBSTITUTE(SUBSTITUTE(SUBSTITUTE(UPPER(TRIM(Asistencia!A7)),"Á","A"),"É","E"),"Í","I"),"Ó","O"),"Ú","U"),"Ñ","N")," "," ")) | AD6: =IF(Asistencia!E7="","",Asistencia!E7) | AE6: =IF(Asistencia!D7="","",UPPER(TRIM(Asistencia!D7))) | AF6: ARMIDA | AG6: =IF(AND(AA6<>"",COUNTIF($AA$5:AA6,AA6)=1),1,0) -> 0 | AH6: =IF(AG6=1,SUM($AG$5:AG6),"") | AI6: =IF(OR(EXACT(Asistencia!F7,"A"),EXACT(Asistencia!F7,"R"),EXACT(Asistencia!F7,"DL"),EXACT(Asistencia!F7,"FL"),EXACT(Asistencia!F7,"FE"),EXACT(Asistencia!F7,"PCS"),EXACT(Asistencia!F7,"V")),1,0) -> 0 | AJ6: =IF(OR(EXACT(Asistencia!G7,"A"),EXACT(Asistencia!G7,"R"),EXACT(Asistencia!G7,"DL"),EXACT(Asistencia!G7,"FL"),EXACT(Asistencia!G7,"FE"),EXACT(Asistencia!G7,"PCS"),EXACT(Asistencia!G7,"V")),1,0) -> 0 | AK6: =IF(OR(EXACT(Asistencia!H7,"A"),EXACT(Asistencia!H7,"R"),EXACT(Asistencia!H7,"DL"),EXACT(Asistencia!H7,"FL"),EXACT(Asistencia!H7,"FE"),EXACT(Asistencia!H7,"PCS"),EXACT(Asistencia!H7,"V")),1,0) -> 0 | AL6: =IF(OR(EXACT(Asistencia!I7,"A"),EXACT(Asistencia!I7,"R"),EXACT(Asistencia!I7,"DL"),EXACT(Asistencia!I7,"FL"),EXACT(Asistencia!I7,"FE"),EXACT(Asistencia!I7,"PCS"),EXACT(Asistencia!I7,"V")),1,0) -> 0 | AM6: =IF(OR(EXACT(Asistencia!J7,"A"),EXACT(Asistencia!J7,"R"),EXACT(Asistencia!J7,"DL"),EXACT(Asistencia!J7,"FL"),EXACT(Asistencia!J7,"FE"),EXACT(Asistencia!J7,"PCS"),EXACT(Asistencia!J7,"V")),1,0) -> 0 | AN6: =IF(OR(EXACT(Asistencia!K7,"A"),EXACT(Asistencia!K7,"R"),EXACT(Asistencia!K7,"DL"),EXACT(Asistencia!K7,"FL"),EXACT(Asistencia!K7,"FE"),EXACT(Asistencia!K7,"PCS"),EXACT(Asistencia!K7,"V")),1,0) -> 0 | AO6: =IF(OR(EXACT(Asistencia!L7,"A"),EXACT(Asistencia!L7,"R"),EXACT(Asistencia!L7,"DL"),EXACT(Asistencia!L7,"FL"),EXACT(Asistencia!L7,"FE"),EXACT(Asistencia!L7,"PCS"),EXACT(Asistencia!L7,"V")),1,0) -> 0 | AP6: =SUM(AI6:AO6) -> 0 | AQ6: =IF(EXACT(Asistencia!F7,"FL"),1,0) -> 0 | AR6: =IF(EXACT(Asistencia!G7,"FL"),1,0) -> 0 | AS6: =IF(EXACT(Asistencia!H7,"FL"),1,0) -> 0 | AT6: =IF(EXACT(Asistencia!I7,"FL"),1,0) -> 0 | AU6: =IF(EXACT(Asistencia!J7,"FL"),1,0) -> 0 | AV6: =IF(EXACT(Asistencia!K7,"FL"),1,0) -> 0 | AW6: =IF(EXACT(Asistencia!L7,"FL"),1,0) -> 0 | AX6: =SUM(AQ6:AW6) -> 0 | AY6: =IF(EXACT(Asistencia!F7,"DL"),1,0) -> 0 | AZ6: =IF(EXACT(Asistencia!G7,"DL"),1,0) -> 0 | BA6: =IF(EXACT(Asistencia!H7,"DL"),1,0) -> 0 | BB6: =IF(EXACT(Asistencia!I7,"DL"),1,0) -> 0 | BC6: =IF(EXACT(Asistencia!J7,"DL"),1,0) -> 0 | BD6: =IF(EXACT(Asistencia!K7,"DL"),1,0) -> 0 | BE6: =IF(EXACT(Asistencia!L7,"DL"),1,0) -> 0 | BF6: =SUM(AY6:BE6) -> 0 | BG6: =IF(ISNUMBER(Asistencia!M7),Asistencia!M7,0) -> 0 | BH6: =IF(ISNUMBER(Asistencia!N7),Asistencia!N7,0) -> 0 | BI6: =IF(ISNUMBER(Asistencia!O7),Asistencia!O7,0) -> 0 | BJ6: =IF(ISNUMBER(Asistencia!P7),Asistencia!P7,0) -> 0 | BK6: =IF(Asistencia!F7="","",Asistencia!F7) | BL6: =IF(Asistencia!G7="","",Asistencia!G7) | BM6: =IF(Asistencia!H7="","",Asistencia!H7) | BN6: =IF(Asistencia!I7="","",Asistencia!I7) | BO6: =IF(Asistencia!J7="","",Asistencia!J7) | BP6: =IF(Asistencia!K7="","",Asistencia!K7) | BQ6: =IF(Asistencia!L7="","",Asistencia!L7)
A7: =IF(Y7="","",INDEX($AB$5:$AB$323,Y7)) | B7: =IF(Y7="","",INDEX($AD$5:$AD$323,Y7)) | E7: =IF($A7="","",_xlfn.TEXTJOIN(" / ",TRUE(),IF(SUMIFS($AP$5:$AP$323,$AA$5:$AA$323,$Z7,$AF$5:$AF$323,"ARMIDA")>0,IFERROR("ARMIDA-"&INDEX($AE$5:$AE$323,MATCH($Z7&"ARMIDA",$AA$5:$AA$323&$AF$5:$AF$323,0)),"ARMIDA"),""),IF(SUMIFS($AP$5:$AP$323,$AA$5:$AA$323,$Z7,$AF$5:$AF$323,"AURIGA")>0,IFERROR("AURIGA-"&INDEX($AE$5:$AE$323,MATCH($Z7&"AURIGA",$AA$5:$AA$323&$AF$5:$AF$323,0)),"AURIGA"),""),IF(SUMIFS($AP$5:$AP$323,$AA$5:$AA$323,$Z7,$AF$5:$AF$323,"AURORA")>0,IFERROR("AURORA-"&INDEX($AE$5:$AE$323,MATCH($Z7&"AURORA",$AA$5:$AA$323&$AF$5:$AF$323,0)),"AURORA"),""),IF(SUMIFS($AP$5:$AP$323,$AA$5:$AA$323,$Z7,$AF$5:$AF$323,"CITICA")>0,IFERROR("CITICA-"&INDEX($AE$5:$AE$323,MATCH($Z7&"CITICA",$AA$5:$AA$323&$AF$5:$AF$323,0)),"CITICA"),""),IF(SUMIFS($AP$5:$AP$323,$AA$5:$AA$323,$Z7,$AF$5:$AF$323,"GM")>0,IFERROR("GM-"&INDEX($AE$5:$AE$323,MATCH($Z7&"GM",$AA$5:$AA$323&$AF$5:$AF$323,0)),"GM"),""),IF(SUMIFS($AP$5:$AP$323,$AA$5:$AA$323,$Z7,$AF$5:$AF$323,"TORRE BALZAK")>0,IFERROR("TORRE BALZAK-"&INDEX($AE$5:$AE$323,MATCH($Z7&"TORRE BALZAK",$AA$5:$AA$323&$AF$5:$AF$323,0)),"TORRE BALZAK"),""),IF(SUMIFS($AP$5:$AP$323,$AA$5:$AA$323,$Z7,$AF$5:$AF$323,"TORRE OLMA")>0,IFERROR("TORRE OLMA-"&INDEX($AE$5:$AE$323,MATCH($Z7&"TORRE OLMA",$AA$5:$AA$323&$AF$5:$AF$323,0)),"TORRE OLMA"),""),IF(SUMIFS($AP$5:$AP$323,$AA$5:$AA$323,$Z7,$AF$5:$AF$323,"OTROS")>0,IFERROR("OTROS-"&INDEX($AE$5:$AE$323,MATCH($Z7&"OTROS",$AA$5:$AA$323&$AF$5:$AF$323,0)),"OTROS"),""))) | F7: =IF($A7="","",IFERROR(INDEX($BK$5:$BK$323,MATCH($Z7,$AA$5:$AA$323,0)),"-")) | G7: =IF($A7="","",IFERROR(INDEX($BL$5:$BL$323,MATCH($Z7,$AA$5:$AA$323,0)),"-")) | H7: =IF($A7="","",IFERROR(INDEX($BM$5:$BM$323,MATCH($Z7,$AA$5:$AA$323,0)),"-")) | I7: =IF($A7="","",IFERROR(INDEX($BN$5:$BN$323,MATCH($Z7,$AA$5:$AA$323,0)),"-")) | J7: =IF($A7="","",IFERROR(INDEX($BO$5:$BO$323,MATCH($Z7,$AA$5:$AA$323,0)),"-")) | K7: =IF($A7="","",IFERROR(INDEX($BP$5:$BP$323,MATCH($Z7,$AA$5:$AA$323,0)),"-")) | L7: =IF($A7="","",IFERROR(INDEX($BQ$5:$BQ$323,MATCH($Z7,$AA$5:$AA$323,0)),"-")) | M7: =IF($A7="","",(--(SUMIF($AA$5:$AA$323,$Z7,$AI$5:$AI$323)>0))+(--(SUMIF($AA$5:$AA$323,$Z7,$AJ$5:$AJ$323)>0))+(--(SUMIF($AA$5:$AA$323,$Z7,$AK$5:$AK$323)>0))+(--(SUMIF($AA$5:$AA$323,$Z7,$AL$5:$AL$323)>0))+(--(SUMIF($AA$5:$AA$323,$Z7,$AM$5:$AM$323)>0))+(--(SUMIF($AA$5:$AA$323,$Z7,$AN$5:$AN$323)>0))+(--(SUMIF($AA$5:$AA$323,$Z7,$AO$5:$AO$323)>0))) | N7: =IF($A7="","",MAX(0,M7-6)) | O7: =IF($A7="","",SUMIF($AA$5:$AA$323,$Z7,$AP$5:$AP$323)-M7) | P7: =IF($A7="","",SUMIF($AA$5:$AA$323,$Z7,$BG$5:$BG$323)) | Q7: =IF($A7="","",SUMIF($AA$5:$AA$323,$Z7,$BH$5:$BH$323)) | R7: =IF($A7="","",SUMIF($AA$5:$AA$323,$Z7,$BI$5:$BI$323)) | U7: =IF($A7="","",SUMIF($AA$5:$AA$323,$Z7,$BJ$5:$BJ$323)) | W7: =IF($A7="","",_xlfn.TEXTJOIN(" | ",TRUE(),IF(N7>0,"+ de 6 días: revisar adicionales",""),IF(O7>0,"Doble evento mismo día: revisar turno/pago",""),IF(SUMIF($AA$5:$AA$323,$Z7,$AX$5:$AX$323)>((--(SUMIF($AA$5:$AA$323,$Z7,$AQ$5:$AQ$323)>0))+(--(SUMIF($AA$5:$AA$323,$Z7,$AR$5:$AR$323)>0))+(--(SUMIF($AA$5:$AA$323,$Z7,$AS$5:$AS$323)>0))+(--(SUMIF($AA$5:$AA$323,$Z7,$AT$5:$AT$323)>0))+(--(SUMIF($AA$5:$AA$323,$Z7,$AU$5:$AU$323)>0))+(--(SUMIF($AA$5:$AA$323,$Z7,$AV$5:$AV$323)>0))+(--(SUMIF($AA$5:$AA$323,$Z7,$AW$5:$AW$323)>0))),"FL múltiple mismo día: revisar pago festivo",""),IF(SUMIF($AA$5:$AA$323,$Z7,$BF$5:$BF$323)>((--(SUMIF($AA$5:$AA$323,$Z7,$AY$5:$AY$323)>0))+(--(SUMIF($AA$5:$AA$323,$Z7,$AZ$5:$AZ$323)>0))+(--(SUMIF($AA$5:$AA$323,$Z7,$BA$5:$BA$323)>0))+(--(SUMIF($AA$5:$AA$323,$Z7,$BB$5:$BB$323)>0))+(--(SUMIF($AA$5:$AA$323,$Z7,$BC$5:$BC$323)>0))+(--(SUMIF($AA$5:$AA$323,$Z7,$BD$5:$BD$323)>0))+(--(SUMIF($AA$5:$AA$323,$Z7,$BE$5:$BE$323)>0))),"DL múltiple mismo día: revisar pago descanso",""))) | Y7: =IFERROR(MATCH(3,$AH$5:$AH$323,0),"") | Z7: =IF(Y7="","",INDEX($AA$5:$AA$323,Y7)) | AA7: =IF(AC7="","","M:"&AC7) | AB7: =IF(Asistencia!A8="","",Asistencia!A8) | AC7: =IF(Asistencia!A8="","",SUBSTITUTE(SUBSTITUTE(SUBSTITUTE(SUBSTITUTE(SUBSTITUTE(SUBSTITUTE(SUBSTITUTE(UPPER(TRIM(Asistencia!A8)),"Á","A"),"É","E"),"Í","I"),"Ó","O"),"Ú","U"),"Ñ","N")," "," ")) | AD7: =IF(Asistencia!E8="","",Asistencia!E8) | AE7: =IF(Asistencia!D8="","",UPPER(TRIM(Asistencia!D8))) | AF7: ARMIDA | AG7: =IF(AND(AA7<>"",COUNTIF($AA$5:AA7,AA7)=1),1,0) -> 0 | AH7: =IF(AG7=1,SUM($AG$5:AG7),"") | AI7: =IF(OR(EXACT(Asistencia!F8,"A"),EXACT(Asistencia!F8,"R"),EXACT(Asistencia!F8,"DL"),EXACT(Asistencia!F8,"FL"),EXACT(Asistencia!F8,"FE"),EXACT(Asistencia!F8,"PCS"),EXACT(Asistencia!F8,"V")),1,0) -> 0 | AJ7: =IF(OR(EXACT(Asistencia!G8,"A"),EXACT(Asistencia!G8,"R"),EXACT(Asistencia!G8,"DL"),EXACT(Asistencia!G8,"FL"),EXACT(Asistencia!G8,"FE"),EXACT(Asistencia!G8,"PCS"),EXACT(Asistencia!G8,"V")),1,0) -> 0 | AK7: =IF(OR(EXACT(Asistencia!H8,"A"),EXACT(Asistencia!H8,"R"),EXACT(Asistencia!H8,"DL"),EXACT(Asistencia!H8,"FL"),EXACT(Asistencia!H8,"FE"),EXACT(Asistencia!H8,"PCS"),EXACT(Asistencia!H8,"V")),1,0) -> 0 | AL7: =IF(OR(EXACT(Asistencia!I8,"A"),EXACT(Asistencia!I8,"R"),EXACT(Asistencia!I8,"DL"),EXACT(Asistencia!I8,"FL"),EXACT(Asistencia!I8,"FE"),EXACT(Asistencia!I8,"PCS"),EXACT(Asistencia!I8,"V")),1,0) -> 0 | AM7: =IF(OR(EXACT(Asistencia!J8,"A"),EXACT(Asistencia!J8,"R"),EXACT(Asistencia!J8,"DL"),EXACT(Asistencia!J8,"FL"),EXACT(Asistencia!J8,"FE"),EXACT(Asistencia!J8,"PCS"),EXACT(Asistencia!J8,"V")),1,0) -> 0 | AN7: =IF(OR(EXACT(Asistencia!K8,"A"),EXACT(Asistencia!K8,"R"),EXACT(Asistencia!K8,"DL"),EXACT(Asistencia!K8,"FL"),EXACT(Asistencia!K8,"FE"),EXACT(Asistencia!K8,"PCS"),EXACT(Asistencia!K8,"V")),1,0) -> 0 | AO7: =IF(OR(EXACT(Asistencia!L8,"A"),EXACT(Asistencia!L8,"R"),EXACT(Asistencia!L8,"DL"),EXACT(Asistencia!L8,"FL"),EXACT(Asistencia!L8,"FE"),EXACT(Asistencia!L8,"PCS"),EXACT(Asistencia!L8,"V")),1,0) -> 0 | AP7: =SUM(AI7:AO7) -> 0 | AQ7: =IF(EXACT(Asistencia!F8,"FL"),1,0) -> 0 | AR7: =IF(EXACT(Asistencia!G8,"FL"),1,0) -> 0 | AS7: =IF(EXACT(Asistencia!H8,"FL"),1,0) -> 0 | AT7: =IF(EXACT(Asistencia!I8,"FL"),1,0) -> 0 | AU7: =IF(EXACT(Asistencia!J8,"FL"),1,0) -> 0 | AV7: =IF(EXACT(Asistencia!K8,"FL"),1,0) -> 0 | AW7: =IF(EXACT(Asistencia!L8,"FL"),1,0) -> 0 | AX7: =SUM(AQ7:AW7) -> 0 | AY7: =IF(EXACT(Asistencia!F8,"DL"),1,0) -> 0 | AZ7: =IF(EXACT(Asistencia!G8,"DL"),1,0) -> 0 | BA7: =IF(EXACT(Asistencia!H8,"DL"),1,0) -> 0 | BB7: =IF(EXACT(Asistencia!I8,"DL"),1,0) -> 0 | BC7: =IF(EXACT(Asistencia!J8,"DL"),1,0) -> 0 | BD7: =IF(EXACT(Asistencia!K8,"DL"),1,0) -> 0 | BE7: =IF(EXACT(Asistencia!L8,"DL"),1,0) -> 0 | BF7: =SUM(AY7:BE7) -> 0 | BG7: =IF(ISNUMBER(Asistencia!M8),Asistencia!M8,0) -> 0 | BH7: =IF(ISNUMBER(Asistencia!N8),Asistencia!N8,0) -> 0 | BI7: =IF(ISNUMBER(Asistencia!O8),Asistencia!O8,0) -> 0 | BJ7: =IF(ISNUMBER(Asistencia!P8),Asistencia!P8,0) -> 0 | BK7: =IF(Asistencia!F8="","",Asistencia!F8) | BL7: =IF(Asistencia!G8="","",Asistencia!G8) | BM7: =IF(Asistencia!H8="","",Asistencia!H8) | BN7: =IF(Asistencia!I8="","",Asistencia!I8) | BO7: =IF(Asistencia!J8="","",Asistencia!J8) | BP7: =IF(Asistencia!K8="","",Asistencia!K8) | BQ7: =IF(Asistencia!L8="","",Asistencia!L8)
A8: =IF(Y8="","",INDEX($AB$5:$AB$323,Y8)) | B8: =IF(Y8="","",INDEX($AD$5:$AD$323,Y8)) | E8: =IF($A8="","",_xlfn.TEXTJOIN(" / ",TRUE(),IF(SUMIFS($AP$5:$AP$323,$AA$5:$AA$323,$Z8,$AF$5:$AF$323,"ARMIDA")>0,IFERROR("ARMIDA-"&INDEX($AE$5:$AE$323,MATCH($Z8&"ARMIDA",$AA$5:$AA$323&$AF$5:$AF$323,0)),"ARMIDA"),""),IF(SUMIFS($AP$5:$AP$323,$AA$5:$AA$323,$Z8,$AF$5:$AF$323,"AURIGA")>0,IFERROR("AURIGA-"&INDEX($AE$5:$AE$323,MATCH($Z8&"AURIGA",$AA$5:$AA$323&$AF$5:$AF$323,0)),"AURIGA"),""),IF(SUMIFS($AP$5:$AP$323,$AA$5:$AA$323,$Z8,$AF$5:$AF$323,"AURORA")>0,IFERROR("AURORA-"&INDEX($AE$5:$AE$323,MATCH($Z8&"AURORA",$AA$5:$AA$323&$AF$5:$AF$323,0)),"AURORA"),""),IF(SUMIFS($AP$5:$AP$323,$AA$5:$AA$323,$Z8,$AF$5:$AF$323,"CITICA")>0,IFERROR("CITICA-"&INDEX($AE$5:$AE$323,MATCH($Z8&"CITICA",$AA$5:$AA$323&$AF$5:$AF$323,0)),"CITICA"),""),IF(SUMIFS($AP$5:$AP$323,$AA$5:$AA$323,$Z8,$AF$5:$AF$323,"GM")>0,IFERROR("GM-"&INDEX($AE$5:$AE$323,MATCH($Z8&"GM",$AA$5:$AA$323&$AF$5:$AF$323,0)),"GM"),""),IF(SUMIFS($AP$5:$AP$323,$AA$5:$AA$323,$Z8,$AF$5:$AF$323,"TORRE BALZAK")>0,IFERROR("TORRE BALZAK-"&INDEX($AE$5:$AE$323,MATCH($Z8&"TORRE BALZAK",$AA$5:$AA$323&$AF$5:$AF$323,0)),"TORRE BALZAK"),""),IF(SUMIFS($AP$5:$AP$323,$AA$5:$AA$323,$Z8,$AF$5:$AF$323,"TORRE OLMA")>0,IFERROR("TORRE OLMA-"&INDEX($AE$5:$AE$323,MATCH($Z8&"TORRE OLMA",$AA$5:$AA$323&$AF$5:$AF$323,0)),"TORRE OLMA"),""),IF(SUMIFS($AP$5:$AP$323,$AA$5:$AA$323,$Z8,$AF$5:$AF$323,"OTROS")>0,IFERROR("OTROS-"&INDEX($AE$5:$AE$323,MATCH($Z8&"OTROS",$AA$5:$AA$323&$AF$5:$AF$323,0)),"OTROS"),""))) | F8: =IF($A8="","",IFERROR(INDEX($BK$5:$BK$323,MATCH($Z8,$AA$5:$AA$323,0)),"-")) | G8: =IF($A8="","",IFERROR(INDEX($BL$5:$BL$323,MATCH($Z8,$AA$5:$AA$323,0)),"-")) | H8: =IF($A8="","",IFERROR(INDEX($BM$5:$BM$323,MATCH($Z8,$AA$5:$AA$323,0)),"-")) | I8: =IF($A8="","",IFERROR(INDEX($BN$5:$BN$323,MATCH($Z8,$AA$5:$AA$323,0)),"-")) | J8: =IF($A8="","",IFERROR(INDEX($BO$5:$BO$323,MATCH($Z8,$AA$5:$AA$323,0)),"-")) | K8: =IF($A8="","",IFERROR(INDEX($BP$5:$BP$323,MATCH($Z8,$AA$5:$AA$323,0)),"-")) | L8: =IF($A8="","",IFERROR(INDEX($BQ$5:$BQ$323,MATCH($Z8,$AA$5:$AA$323,0)),"-")) | M8: =IF($A8="","",(--(SUMIF($AA$5:$AA$323,$Z8,$AI$5:$AI$323)>0))+(--(SUMIF($AA$5:$AA$323,$Z8,$AJ$5:$AJ$323)>0))+(--(SUMIF($AA$5:$AA$323,$Z8,$AK$5:$AK$323)>0))+(--(SUMIF($AA$5:$AA$323,$Z8,$AL$5:$AL$323)>0))+(--(SUMIF($AA$5:$AA$323,$Z8,$AM$5:$AM$323)>0))+(--(SUMIF($AA$5:$AA$323,$Z8,$AN$5:$AN$323)>0))+(--(SUMIF($AA$5:$AA$323,$Z8,$AO$5:$AO$323)>0))) | N8: =IF($A8="","",MAX(0,M8-6)) | O8: =IF($A8="","",SUMIF($AA$5:$AA$323,$Z8,$AP$5:$AP$323)-M8) | P8: =IF($A8="","",SUMIF($AA$5:$AA$323,$Z8,$BG$5:$BG$323)) | Q8: =IF($A8="","",SUMIF($AA$5:$AA$323,$Z8,$BH$5:$BH$323)) | R8: =IF($A8="","",SUMIF($AA$5:$AA$323,$Z8,$BI$5:$BI$323)) | U8: =IF($A8="","",SUMIF($AA$5:$AA$323,$Z8,$BJ$5:$BJ$323)) | W8: =IF($A8="","",_xlfn.TEXTJOIN(" | ",TRUE(),IF(N8>0,"+ de 6 días: revisar adicionales",""),IF(O8>0,"Doble evento mismo día: revisar turno/pago",""),IF(SUMIF($AA$5:$AA$323,$Z8,$AX$5:$AX$323)>((--(SUMIF($AA$5:$AA$323,$Z8,$AQ$5:$AQ$323)>0))+(--(SUMIF($AA$5:$AA$323,$Z8,$AR$5:$AR$323)>0))+(--(SUMIF($AA$5:$AA$323,$Z8,$AS$5:$AS$323)>0))+(--(SUMIF($AA$5:$AA$323,$Z8,$AT$5:$AT$323)>0))+(--(SUMIF($AA$5:$AA$323,$Z8,$AU$5:$AU$323)>0))+(--(SUMIF($AA$5:$AA$323,$Z8,$AV$5:$AV$323)>0))+(--(SUMIF($AA$5:$AA$323,$Z8,$AW$5:$AW$323)>0))),"FL múltiple mismo día: revisar pago festivo",""),IF(SUMIF($AA$5:$AA$323,$Z8,$BF$5:$BF$323)>((--(SUMIF($AA$5:$AA$323,$Z8,$AY$5:$AY$323)>0))+(--(SUMIF($AA$5:$AA$323,$Z8,$AZ$5:$AZ$323)>0))+(--(SUMIF($AA$5:$AA$323,$Z8,$BA$5:$BA$323)>0))+(--(SUMIF($AA$5:$AA$323,$Z8,$BB$5:$BB$323)>0))+(--(SUMIF($AA$5:$AA$323,$Z8,$BC$5:$BC$323)>0))+(--(SUMIF($AA$5:$AA$323,$Z8,$BD$5:$BD$323)>0))+(--(SUMIF($AA$5:$AA$323,$Z8,$BE$5:$BE$323)>0))),"DL múltiple mismo día: revisar pago descanso",""))) | Y8: =IFERROR(MATCH(4,$AH$5:$AH$323,0),"") | Z8: =IF(Y8="","",INDEX($AA$5:$AA$323,Y8)) | AA8: =IF(AC8="","","M:"&AC8) | AB8: =IF(Asistencia!A9="","",Asistencia!A9) | AC8: =IF(Asistencia!A9="","",SUBSTITUTE(SUBSTITUTE(SUBSTITUTE(SUBSTITUTE(SUBSTITUTE(SUBSTITUTE(SUBSTITUTE(UPPER(TRIM(Asistencia!A9)),"Á","A"),"É","E"),"Í","I"),"Ó","O"),"Ú","U"),"Ñ","N")," "," ")) | AD8: =IF(Asistencia!E9="","",Asistencia!E9) | AE8: =IF(Asistencia!D9="","",UPPER(TRIM(Asistencia!D9))) | AF8: ARMIDA | AG8: =IF(AND(AA8<>"",COUNTIF($AA$5:AA8,AA8)=1),1,0) -> 0 | AH8: =IF(AG8=1,SUM($AG$5:AG8),"") | AI8: =IF(OR(EXACT(Asistencia!F9,"A"),EXACT(Asistencia!F9,"R"),EXACT(Asistencia!F9,"DL"),EXACT(Asistencia!F9,"FL"),EXACT(Asistencia!F9,"FE"),EXACT(Asistencia!F9,"PCS"),EXACT(Asistencia!F9,"V")),1,0) -> 0 | AJ8: =IF(OR(EXACT(Asistencia!G9,"A"),EXACT(Asistencia!G9,"R"),EXACT(Asistencia!G9,"DL"),EXACT(Asistencia!G9,"FL"),EXACT(Asistencia!G9,"FE"),EXACT(Asistencia!G9,"PCS"),EXACT(Asistencia!G9,"V")),1,0) -> 0 | AK8: =IF(OR(EXACT(Asistencia!H9,"A"),EXACT(Asistencia!H9,"R"),EXACT(Asistencia!H9,"DL"),EXACT(Asistencia!H9,"FL"),EXACT(Asistencia!H9,"FE"),EXACT(Asistencia!H9,"PCS"),EXACT(Asistencia!H9,"V")),1,0) -> 0 | AL8: =IF(OR(EXACT(Asistencia!I9,"A"),EXACT(Asistencia!I9,"R"),EXACT(Asistencia!I9,"DL"),EXACT(Asistencia!I9,"FL"),EXACT(Asistencia!I9,"FE"),EXACT(Asistencia!I9,"PCS"),EXACT(Asistencia!I9,"V")),1,0) -> 0 | AM8: =IF(OR(EXACT(Asistencia!J9,"A"),EXACT(Asistencia!J9,"R"),EXACT(Asistencia!J9,"DL"),EXACT(Asistencia!J9,"FL"),EXACT(Asistencia!J9,"FE"),EXACT(Asistencia!J9,"PCS"),EXACT(Asistencia!J9,"V")),1,0) -> 0 | AN8: =IF(OR(EXACT(Asistencia!K9,"A"),EXACT(Asistencia!K9,"R"),EXACT(Asistencia!K9,"DL"),EXACT(Asistencia!K9,"FL"),EXACT(Asistencia!K9,"FE"),EXACT(Asistencia!K9,"PCS"),EXACT(Asistencia!K9,"V")),1,0) -> 0 | AO8: =IF(OR(EXACT(Asistencia!L9,"A"),EXACT(Asistencia!L9,"R"),EXACT(Asistencia!L9,"DL"),EXACT(Asistencia!L9,"FL"),EXACT(Asistencia!L9,"FE"),EXACT(Asistencia!L9,"PCS"),EXACT(Asistencia!L9,"V")),1,0) -> 0 | AP8: =SUM(AI8:AO8) -> 0 | AQ8: =IF(EXACT(Asistencia!F9,"FL"),1,0) -> 0 | AR8: =IF(EXACT(Asistencia!G9,"FL"),1,0) -> 0 | AS8: =IF(EXACT(Asistencia!H9,"FL"),1,0) -> 0 | AT8: =IF(EXACT(Asistencia!I9,"FL"),1,0) -> 0 | AU8: =IF(EXACT(Asistencia!J9,"FL"),1,0) -> 0 | AV8: =IF(EXACT(Asistencia!K9,"FL"),1,0) -> 0 | AW8: =IF(EXACT(Asistencia!L9,"FL"),1,0) -> 0 | AX8: =SUM(AQ8:AW8) -> 0 | AY8: =IF(EXACT(Asistencia!F9,"DL"),1,0) -> 0 | AZ8: =IF(EXACT(Asistencia!G9,"DL"),1,0) -> 0 | BA8: =IF(EXACT(Asistencia!H9,"DL"),1,0) -> 0 | BB8: =IF(EXACT(Asistencia!I9,"DL"),1,0) -> 0 | BC8: =IF(EXACT(Asistencia!J9,"DL"),1,0) -> 0 | BD8: =IF(EXACT(Asistencia!K9,"DL"),1,0) -> 0 | BE8: =IF(EXACT(Asistencia!L9,"DL"),1,0) -> 0 | BF8: =SUM(AY8:BE8) -> 0 | BG8: =IF(ISNUMBER(Asistencia!M9),Asistencia!M9,0) -> 0 | BH8: =IF(ISNUMBER(Asistencia!N9),Asistencia!N9,0) -> 0 | BI8: =IF(ISNUMBER(Asistencia!O9),Asistencia!O9,0) -> 0 | BJ8: =IF(ISNUMBER(Asistencia!P9),Asistencia!P9,0) -> 0 | BK8: =IF(Asistencia!F9="","",Asistencia!F9) | BL8: =IF(Asistencia!G9="","",Asistencia!G9) | BM8: =IF(Asistencia!H9="","",Asistencia!H9) | BN8: =IF(Asistencia!I9="","",Asistencia!I9) | BO8: =IF(Asistencia!J9="","",Asistencia!J9) | BP8: =IF(Asistencia!K9="","",Asistencia!K9) | BQ8: =IF(Asistencia!L9="","",Asistencia!L9)
A9: =IF(Y9="","",INDEX($AB$5:$AB$323,Y9)) | B9: =IF(Y9="","",INDEX($AD$5:$AD$323,Y9)) | E9: =IF($A9="","",_xlfn.TEXTJOIN(" / ",TRUE(),IF(SUMIFS($AP$5:$AP$323,$AA$5:$AA$323,$Z9,$AF$5:$AF$323,"ARMIDA")>0,IFERROR("ARMIDA-"&INDEX($AE$5:$AE$323,MATCH($Z9&"ARMIDA",$AA$5:$AA$323&$AF$5:$AF$323,0)),"ARMIDA"),""),IF(SUMIFS($AP$5:$AP$323,$AA$5:$AA$323,$Z9,$AF$5:$AF$323,"AURIGA")>0,IFERROR("AURIGA-"&INDEX($AE$5:$AE$323,MATCH($Z9&"AURIGA",$AA$5:$AA$323&$AF$5:$AF$323,0)),"AURIGA"),""),IF(SUMIFS($AP$5:$AP$323,$AA$5:$AA$323,$Z9,$AF$5:$AF$323,"AURORA")>0,IFERROR("AURORA-"&INDEX($AE$5:$AE$323,MATCH($Z9&"AURORA",$AA$5:$AA$323&$AF$5:$AF$323,0)),"AURORA"),""),IF(SUMIFS($AP$5:$AP$323,$AA$5:$AA$323,$Z9,$AF$5:$AF$323,"CITICA")>0,IFERROR("CITICA-"&INDEX($AE$5:$AE$323,MATCH($Z9&"CITICA",$AA$5:$AA$323&$AF$5:$AF$323,0)),"CITICA"),""),IF(SUMIFS($AP$5:$AP$323,$AA$5:$AA$323,$Z9,$AF$5:$AF$323,"GM")>0,IFERROR("GM-"&INDEX($AE$5:$AE$323,MATCH($Z9&"GM",$AA$5:$AA$323&$AF$5:$AF$323,0)),"GM"),""),IF(SUMIFS($AP$5:$AP$323,$AA$5:$AA$323,$Z9,$AF$5:$AF$323,"TORRE BALZAK")>0,IFERROR("TORRE BALZAK-"&INDEX($AE$5:$AE$323,MATCH($Z9&"TORRE BALZAK",$AA$5:$AA$323&$AF$5:$AF$323,0)),"TORRE BALZAK"),""),IF(SUMIFS($AP$5:$AP$323,$AA$5:$AA$323,$Z9,$AF$5:$AF$323,"TORRE OLMA")>0,IFERROR("TORRE OLMA-"&INDEX($AE$5:$AE$323,MATCH($Z9&"TORRE OLMA",$AA$5:$AA$323&$AF$5:$AF$323,0)),"TORRE OLMA"),""),IF(SUMIFS($AP$5:$AP$323,$AA$5:$AA$323,$Z9,$AF$5:$AF$323,"OTROS")>0,IFERROR("OTROS-"&INDEX($AE$5:$AE$323,MATCH($Z9&"OTROS",$AA$5:$AA$323&$AF$5:$AF$323,0)),"OTROS"),""))) | F9: =IF($A9="","",IFERROR(INDEX($BK$5:$BK$323,MATCH($Z9,$AA$5:$AA$323,0)),"-")) | G9: =IF($A9="","",IFERROR(INDEX($BL$5:$BL$323,MATCH($Z9,$AA$5:$AA$323,0)),"-")) | H9: =IF($A9="","",IFERROR(INDEX($BM$5:$BM$323,MATCH($Z9,$AA$5:$AA$323,0)),"-")) | I9: =IF($A9="","",IFERROR(INDEX($BN$5:$BN$323,MATCH($Z9,$AA$5:$AA$323,0)),"-")) | J9: =IF($A9="","",IFERROR(INDEX($BO$5:$BO$323,MATCH($Z9,$AA$5:$AA$323,0)),"-")) | K9: =IF($A9="","",IFERROR(INDEX($BP$5:$BP$323,MATCH($Z9,$AA$5:$AA$323,0)),"-")) | L9: =IF($A9="","",IFERROR(INDEX($BQ$5:$BQ$323,MATCH($Z9,$AA$5:$AA$323,0)),"-")) | M9: =IF($A9="","",(--(SUMIF($AA$5:$AA$323,$Z9,$AI$5:$AI$323)>0))+(--(SUMIF($AA$5:$AA$323,$Z9,$AJ$5:$AJ$323)>0))+(--(SUMIF($AA$5:$AA$323,$Z9,$AK$5:$AK$323)>0))+(--(SUMIF($AA$5:$AA$323,$Z9,$AL$5:$AL$323)>0))+(--(SUMIF($AA$5:$AA$323,$Z9,$AM$5:$AM$323)>0))+(--(SUMIF($AA$5:$AA$323,$Z9,$AN$5:$AN$323)>0))+(--(SUMIF($AA$5:$AA$323,$Z9,$AO$5:$AO$323)>0))) | N9: =IF($A9="","",MAX(0,M9-6)) | O9: =IF($A9="","",SUMIF($AA$5:$AA$323,$Z9,$AP$5:$AP$323)-M9) | P9: =IF($A9="","",SUMIF($AA$5:$AA$323,$Z9,$BG$5:$BG$323)) | Q9: =IF($A9="","",SUMIF($AA$5:$AA$323,$Z9,$BH$5:$BH$323)) | R9: =IF($A9="","",SUMIF($AA$5:$AA$323,$Z9,$BI$5:$BI$323)) | U9: =IF($A9="","",SUMIF($AA$5:$AA$323,$Z9,$BJ$5:$BJ$323)) | W9: =IF($A9="","",_xlfn.TEXTJOIN(" | ",TRUE(),IF(N9>0,"+ de 6 días: revisar adicionales",""),IF(O9>0,"Doble evento mismo día: revisar turno/pago",""),IF(SUMIF($AA$5:$AA$323,$Z9,$AX$5:$AX$323)>((--(SUMIF($AA$5:$AA$323,$Z9,$AQ$5:$AQ$323)>0))+(--(SUMIF($AA$5:$AA$323,$Z9,$AR$5:$AR$323)>0))+(--(SUMIF($AA$5:$AA$323,$Z9,$AS$5:$AS$323)>0))+(--(SUMIF($AA$5:$AA$323,$Z9,$AT$5:$AT$323)>0))+(--(SUMIF($AA$5:$AA$323,$Z9,$AU$5:$AU$323)>0))+(--(SUMIF($AA$5:$AA$323,$Z9,$AV$5:$AV$323)>0))+(--(SUMIF($AA$5:$AA$323,$Z9,$AW$5:$AW$323)>0))),"FL múltiple mismo día: revisar pago festivo",""),IF(SUMIF($AA$5:$AA$323,$Z9,$BF$5:$BF$323)>((--(SUMIF($AA$5:$AA$323,$Z9,$AY$5:$AY$323)>0))+(--(SUMIF($AA$5:$AA$323,$Z9,$AZ$5:$AZ$323)>0))+(--(SUMIF($AA$5:$AA$323,$Z9,$BA$5:$BA$323)>0))+(--(SUMIF($AA$5:$AA$323,$Z9,$BB$5:$BB$323)>0))+(--(SUMIF($AA$5:$AA$323,$Z9,$BC$5:$BC$323)>0))+(--(SUMIF($AA$5:$AA$323,$Z9,$BD$5:$BD$323)>0))+(--(SUMIF($AA$5:$AA$323,$Z9,$BE$5:$BE$323)>0))),"DL múltiple mismo día: revisar pago descanso",""))) | Y9: =IFERROR(MATCH(5,$AH$5:$AH$323,0),"") | Z9: =IF(Y9="","",INDEX($AA$5:$AA$323,Y9)) | AA9: =IF(AC9="","","M:"&AC9) | AB9: =IF(Asistencia!A10="","",Asistencia!A10) | AC9: =IF(Asistencia!A10="","",SUBSTITUTE(SUBSTITUTE(SUBSTITUTE(SUBSTITUTE(SUBSTITUTE(SUBSTITUTE(SUBSTITUTE(UPPER(TRIM(Asistencia!A10)),"Á","A"),"É","E"),"Í","I"),"Ó","O"),"Ú","U"),"Ñ","N")," "," ")) | AD9: =IF(Asistencia!E10="","",Asistencia!E10) | AE9: =IF(Asistencia!D10="","",UPPER(TRIM(Asistencia!D10))) | AF9: ARMIDA | AG9: =IF(AND(AA9<>"",COUNTIF($AA$5:AA9,AA9)=1),1,0) -> 0 | AH9: =IF(AG9=1,SUM($AG$5:AG9),"") | AI9: =IF(OR(EXACT(Asistencia!F10,"A"),EXACT(Asistencia!F10,"R"),EXACT(Asistencia!F10,"DL"),EXACT(Asistencia!F10,"FL"),EXACT(Asistencia!F10,"FE"),EXACT(Asistencia!F10,"PCS"),EXACT(Asistencia!F10,"V")),1,0) -> 0 | AJ9: =IF(OR(EXACT(Asistencia!G10,"A"),EXACT(Asistencia!G10,"R"),EXACT(Asistencia!G10,"DL"),EXACT(Asistencia!G10,"FL"),EXACT(Asistencia!G10,"FE"),EXACT(Asistencia!G10,"PCS"),EXACT(Asistencia!G10,"V")),1,0) -> 0 | AK9: =IF(OR(EXACT(Asistencia!H10,"A"),EXACT(Asistencia!H10,"R"),EXACT(Asistencia!H10,"DL"),EXACT(Asistencia!H10,"FL"),EXACT(Asistencia!H10,"FE"),EXACT(Asistencia!H10,"PCS"),EXACT(Asistencia!H10,"V")),1,0) -> 0 | AL9: =IF(OR(EXACT(Asistencia!I10,"A"),EXACT(Asistencia!I10,"R"),EXACT(Asistencia!I10,"DL"),EXACT(Asistencia!I10,"FL"),EXACT(Asistencia!I10,"FE"),EXACT(Asistencia!I10,"PCS"),EXACT(Asistencia!I10,"V")),1,0) -> 0 | AM9: =IF(OR(EXACT(Asistencia!J10,"A"),EXACT(Asistencia!J10,"R"),EXACT(Asistencia!J10,"DL"),EXACT(Asistencia!J10,"FL"),EXACT(Asistencia!J10,"FE"),EXACT(Asistencia!J10,"PCS"),EXACT(Asistencia!J10,"V")),1,0) -> 0 | AN9: =IF(OR(EXACT(Asistencia!K10,"A"),EXACT(Asistencia!K10,"R"),EXACT(Asistencia!K10,"DL"),EXACT(Asistencia!K10,"FL"),EXACT(Asistencia!K10,"FE"),EXACT(Asistencia!K10,"PCS"),EXACT(Asistencia!K10,"V")),1,0) -> 0 | AO9: =IF(OR(EXACT(Asistencia!L10,"A"),EXACT(Asistencia!L10,"R"),EXACT(Asistencia!L10,"DL"),EXACT(Asistencia!L10,"FL"),EXACT(Asistencia!L10,"FE"),EXACT(Asistencia!L10,"PCS"),EXACT(Asistencia!L10,"V")),1,0) -> 0 | AP9: =SUM(AI9:AO9) -> 0 | AQ9: =IF(EXACT(Asistencia!F10,"FL"),1,0) -> 0 | AR9: =IF(EXACT(Asistencia!G10,"FL"),1,0) -> 0 | AS9: =IF(EXACT(Asistencia!H10,"FL"),1,0) -> 0 | AT9: =IF(EXACT(Asistencia!I10,"FL"),1,0) -> 0 | AU9: =IF(EXACT(Asistencia!J10,"FL"),1,0) -> 0 | AV9: =IF(EXACT(Asistencia!K10,"FL"),1,0) -> 0 | AW9: =IF(EXACT(Asistencia!L10,"FL"),1,0) -> 0 | AX9: =SUM(AQ9:AW9) -> 0 | AY9: =IF(EXACT(Asistencia!F10,"DL"),1,0) -> 0 | AZ9: =IF(EXACT(Asistencia!G10,"DL"),1,0) -> 0 | BA9: =IF(EXACT(Asistencia!H10,"DL"),1,0) -> 0 | BB9: =IF(EXACT(Asistencia!I10,"DL"),1,0) -> 0 | BC9: =IF(EXACT(Asistencia!J10,"DL"),1,0) -> 0 | BD9: =IF(EXACT(Asistencia!K10,"DL"),1,0) -> 0 | BE9: =IF(EXACT(Asistencia!L10,"DL"),1,0) -> 0 | BF9: =SUM(AY9:BE9) -> 0 | BG9: =IF(ISNUMBER(Asistencia!M10),Asistencia!M10,0) -> 0 | BH9: =IF(ISNUMBER(Asistencia!N10),Asistencia!N10,0) -> 0 | BI9: =IF(ISNUMBER(Asistencia!O10),Asistencia!O10,0) -> 0 | BJ9: =IF(ISNUMBER(Asistencia!P10),Asistencia!P10,0) -> 0 | BK9: =IF(Asistencia!F10="","",Asistencia!F10) | BL9: =IF(Asistencia!G10="","",Asistencia!G10) | BM9: =IF(Asistencia!H10="","",Asistencia!H10) | BN9: =IF(Asistencia!I10="","",Asistencia!I10) | BO9: =IF(Asistencia!J10="","",Asistencia!J10) | BP9: =IF(Asistencia!K10="","",Asistencia!K10) | BQ9: =IF(Asistencia!L10="","",Asistencia!L10)
A10: =IF(Y10="","",INDEX($AB$5:$AB$323,Y10)) | B10: =IF(Y10="","",INDEX($AD$5:$AD$323,Y10)) | E10: =IF($A10="","",_xlfn.TEXTJOIN(" / ",TRUE(),IF(SUMIFS($AP$5:$AP$323,$AA$5:$AA$323,$Z10,$AF$5:$AF$323,"ARMIDA")>0,IFERROR("ARMIDA-"&INDEX($AE$5:$AE$323,MATCH($Z10&"ARMIDA",$AA$5:$AA$323&$AF$5:$AF$323,0)),"ARMIDA"),""),IF(SUMIFS($AP$5:$AP$323,$AA$5:$AA$323,$Z10,$AF$5:$AF$323,"AURIGA")>0,IFERROR("AURIGA-"&INDEX($AE$5:$AE$323,MATCH($Z10&"AURIGA",$AA$5:$AA$323&$AF$5:$AF$323,0)),"AURIGA"),""),IF(SUMIFS($AP$5:$AP$323,$AA$5:$AA$323,$Z10,$AF$5:$AF$323,"AURORA")>0,IFERROR("AURORA-"&INDEX($AE$5:$AE$323,MATCH($Z10&"AURORA",$AA$5:$AA$323&$AF$5:$AF$323,0)),"AURORA"),""),IF(SUMIFS($AP$5:$AP$323,$AA$5:$AA$323,$Z10,$AF$5:$AF$323,"CITICA")>0,IFERROR("CITICA-"&INDEX($AE$5:$AE$323,MATCH($Z10&"CITICA",$AA$5:$AA$323&$AF$5:$AF$323,0)),"CITICA"),""),IF(SUMIFS($AP$5:$AP$323,$AA$5:$AA$323,$Z10,$AF$5:$AF$323,"GM")>0,IFERROR("GM-"&INDEX($AE$5:$AE$323,MATCH($Z10&"GM",$AA$5:$AA$323&$AF$5:$AF$323,0)),"GM"),""),IF(SUMIFS($AP$5:$AP$323,$AA$5:$AA$323,$Z10,$AF$5:$AF$323,"TORRE BALZAK")>0,IFERROR("TORRE BALZAK-"&INDEX($AE$5:$AE$323,MATCH($Z10&"TORRE BALZAK",$AA$5:$AA$323&$AF$5:$AF$323,0)),"TORRE BALZAK"),""),IF(SUMIFS($AP$5:$AP$323,$AA$5:$AA$323,$Z10,$AF$5:$AF$323,"TORRE OLMA")>0,IFERROR("TORRE OLMA-"&INDEX($AE$5:$AE$323,MATCH($Z10&"TORRE OLMA",$AA$5:$AA$323&$AF$5:$AF$323,0)),"TORRE OLMA"),""),IF(SUMIFS($AP$5:$AP$323,$AA$5:$AA$323,$Z10,$AF$5:$AF$323,"OTROS")>0,IFERROR("OTROS-"&INDEX($AE$5:$AE$323,MATCH($Z10&"OTROS",$AA$5:$AA$323&$AF$5:$AF$323,0)),"OTROS"),""))) | F10: =IF($A10="","",IFERROR(INDEX($BK$5:$BK$323,MATCH($Z10,$AA$5:$AA$323,0)),"-")) | G10: =IF($A10="","",IFERROR(INDEX($BL$5:$BL$323,MATCH($Z10,$AA$5:$AA$323,0)),"-")) | H10: =IF($A10="","",IFERROR(INDEX($BM$5:$BM$323,MATCH($Z10,$AA$5:$AA$323,0)),"-")) | I10: =IF($A10="","",IFERROR(INDEX($BN$5:$BN$323,MATCH($Z10,$AA$5:$AA$323,0)),"-")) | J10: =IF($A10="","",IFERROR(INDEX($BO$5:$BO$323,MATCH($Z10,$AA$5:$AA$323,0)),"-")) | K10: =IF($A10="","",IFERROR(INDEX($BP$5:$BP$323,MATCH($Z10,$AA$5:$AA$323,0)),"-")) | L10: =IF($A10="","",IFERROR(INDEX($BQ$5:$BQ$323,MATCH($Z10,$AA$5:$AA$323,0)),"-")) | M10: =IF($A10="","",(--(SUMIF($AA$5:$AA$323,$Z10,$AI$5:$AI$323)>0))+(--(SUMIF($AA$5:$AA$323,$Z10,$AJ$5:$AJ$323)>0))+(--(SUMIF($AA$5:$AA$323,$Z10,$AK$5:$AK$323)>0))+(--(SUMIF($AA$5:$AA$323,$Z10,$AL$5:$AL$323)>0))+(--(SUMIF($AA$5:$AA$323,$Z10,$AM$5:$AM$323)>0))+(--(SUMIF($AA$5:$AA$323,$Z10,$AN$5:$AN$323)>0))+(--(SUMIF($AA$5:$AA$323,$Z10,$AO$5:$AO$323)>0))) | N10: =IF($A10="","",MAX(0,M10-6)) | O10: =IF($A10="","",SUMIF($AA$5:$AA$323,$Z10,$AP$5:$AP$323)-M10) | P10: =IF($A10="","",SUMIF($AA$5:$AA$323,$Z10,$BG$5:$BG$323)) | Q10: =IF($A10="","",SUMIF($AA$5:$AA$323,$Z10,$BH$5:$BH$323)) | R10: =IF($A10="","",SUMIF($AA$5:$AA$323,$Z10,$BI$5:$BI$323)) | U10: =IF($A10="","",SUMIF($AA$5:$AA$323,$Z10,$BJ$5:$BJ$323)) | W10: =IF($A10="","",_xlfn.TEXTJOIN(" | ",TRUE(),IF(N10>0,"+ de 6 días: revisar adicionales",""),IF(O10>0,"Doble evento mismo día: revisar turno/pago",""),IF(SUMIF($AA$5:$AA$323,$Z10,$AX$5:$AX$323)>((--(SUMIF($AA$5:$AA$323,$Z10,$AQ$5:$AQ$323)>0))+(--(SUMIF($AA$5:$AA$323,$Z10,$AR$5:$AR$323)>0))+(--(SUMIF($AA$5:$AA$323,$Z10,$AS$5:$AS$323)>0))+(--(SUMIF($AA$5:$AA$323,$Z10,$AT$5:$AT$323)>0))+(--(SUMIF($AA$5:$AA$323,$Z10,$AU$5:$AU$323)>0))+(--(SUMIF($AA$5:$AA$323,$Z10,$AV$5:$AV$323)>0))+(--(SUMIF($AA$5:$AA$323,$Z10,$AW$5:$AW$323)>0))),"FL múltiple mismo día: revisar pago festivo",""),IF(SUMIF($AA$5:$AA$323,$Z10,$BF$5:$BF$323)>((--(SUMIF($AA$5:$AA$323,$Z10,$AY$5:$AY$323)>0))+(--(SUMIF($AA$5:$AA$323,$Z10,$AZ$5:$AZ$323)>0))+(--(SUMIF($AA$5:$AA$323,$Z10,$BA$5:$BA$323)>0))+(--(SUMIF($AA$5:$AA$323,$Z10,$BB$5:$BB$323)>0))+(--(SUMIF($AA$5:$AA$323,$Z10,$BC$5:$BC$323)>0))+(--(SUMIF($AA$5:$AA$323,$Z10,$BD$5:$BD$323)>0))+(--(SUMIF($AA$5:$AA$323,$Z10,$BE$5:$BE$323)>0))),"DL múltiple mismo día: revisar pago descanso",""))) | Y10: =IFERROR(MATCH(6,$AH$5:$AH$323,0),"") | Z10: =IF(Y10="","",INDEX($AA$5:$AA$323,Y10)) | AA10: =IF(AC10="","","M:"&AC10) | AB10: =IF(Asistencia!A11="","",Asistencia!A11) | AC10: =IF(Asistencia!A11="","",SUBSTITUTE(SUBSTITUTE(SUBSTITUTE(SUBSTITUTE(SUBSTITUTE(SUBSTITUTE(SUBSTITUTE(UPPER(TRIM(Asistencia!A11)),"Á","A"),"É","E"),"Í","I"),"Ó","O"),"Ú","U"),"Ñ","N")," "," ")) | AD10: =IF(Asistencia!E11="","",Asistencia!E11) | AE10: =IF(Asistencia!D11="","",UPPER(TRIM(Asistencia!D11))) | AF10: ARMIDA | AG10: =IF(AND(AA10<>"",COUNTIF($AA$5:AA10,AA10)=1),1,0) -> 0 | AH10: =IF(AG10=1,SUM($AG$5:AG10),"") | AI10: =IF(OR(EXACT(Asistencia!F11,"A"),EXACT(Asistencia!F11,"R"),EXACT(Asistencia!F11,"DL"),EXACT(Asistencia!F11,"FL"),EXACT(Asistencia!F11,"FE"),EXACT(Asistencia!F11,"PCS"),EXACT(Asistencia!F11,"V")),1,0) -> 0 | AJ10: =IF(OR(EXACT(Asistencia!G11,"A"),EXACT(Asistencia!G11,"R"),EXACT(Asistencia!G11,"DL"),EXACT(Asistencia!G11,"FL"),EXACT(Asistencia!G11,"FE"),EXACT(Asistencia!G11,"PCS"),EXACT(Asistencia!G11,"V")),1,0) -> 0 | AK10: =IF(OR(EXACT(Asistencia!H11,"A"),EXACT(Asistencia!H11,"R"),EXACT(Asistencia!H11,"DL"),EXACT(Asistencia!H11,"FL"),EXACT(Asistencia!H11,"FE"),EXACT(Asistencia!H11,"PCS"),EXACT(Asistencia!H11,"V")),1,0) -> 0 | AL10: =IF(OR(EXACT(Asistencia!I11,"A"),EXACT(Asistencia!I11,"R"),EXACT(Asistencia!I11,"DL"),EXACT(Asistencia!I11,"FL"),EXACT(Asistencia!I11,"FE"),EXACT(Asistencia!I11,"PCS"),EXACT(Asistencia!I11,"V")),1,0) -> 0 | AM10: =IF(OR(EXACT(Asistencia!J11,"A"),EXACT(Asistencia!J11,"R"),EXACT(Asistencia!J11,"DL"),EXACT(Asistencia!J11,"FL"),EXACT(Asistencia!J11,"FE"),EXACT(Asistencia!J11,"PCS"),EXACT(Asistencia!J11,"V")),1,0) -> 0 | AN10: =IF(OR(EXACT(Asistencia!K11,"A"),EXACT(Asistencia!K11,"R"),EXACT(Asistencia!K11,"DL"),EXACT(Asistencia!K11,"FL"),EXACT(Asistencia!K11,"FE"),EXACT(Asistencia!K11,"PCS"),EXACT(Asistencia!K11,"V")),1,0) -> 0 | AO10: =IF(OR(EXACT(Asistencia!L11,"A"),EXACT(Asistencia!L11,"R"),EXACT(Asistencia!L11,"DL"),EXACT(Asistencia!L11,"FL"),EXACT(Asistencia!L11,"FE"),EXACT(Asistencia!L11,"PCS"),EXACT(Asistencia!L11,"V")),1,0) -> 0 | AP10: =SUM(AI10:AO10) -> 0 | AQ10: =IF(EXACT(Asistencia!F11,"FL"),1,0) -> 0 | AR10: =IF(EXACT(Asistencia!G11,"FL"),1,0) -> 0 | AS10: =IF(EXACT(Asistencia!H11,"FL"),1,0) -> 0 | AT10: =IF(EXACT(Asistencia!I11,"FL"),1,0) -> 0 | AU10: =IF(EXACT(Asistencia!J11,"FL"),1,0) -> 0 | AV10: =IF(EXACT(Asistencia!K11,"FL"),1,0) -> 0 | AW10: =IF(EXACT(Asistencia!L11,"FL"),1,0) -> 0 | AX10: =SUM(AQ10:AW10) -> 0 | AY10: =IF(EXACT(Asistencia!F11,"DL"),1,0) -> 0 | AZ10: =IF(EXACT(Asistencia!G11,"DL"),1,0) -> 0 | BA10: =IF(EXACT(Asistencia!H11,"DL"),1,0) -> 0 | BB10: =IF(EXACT(Asistencia!I11,"DL"),1,0) -> 0 | BC10: =IF(EXACT(Asistencia!J11,"DL"),1,0) -> 0 | BD10: =IF(EXACT(Asistencia!K11,"DL"),1,0) -> 0 | BE10: =IF(EXACT(Asistencia!L11,"DL"),1,0) -> 0 | BF10: =SUM(AY10:BE10) -> 0 | BG10: =IF(ISNUMBER(Asistencia!M11),Asistencia!M11,0) -> 0 | BH10: =IF(ISNUMBER(Asistencia!N11),Asistencia!N11,0) -> 0 | BI10: =IF(ISNUMBER(Asistencia!O11),Asistencia!O11,0) -> 0 | BJ10: =IF(ISNUMBER(Asistencia!P11),Asistencia!P11,0) -> 0 | BK10: =IF(Asistencia!F11="","",Asistencia!F11) | BL10: =IF(Asistencia!G11="","",Asistencia!G11) | BM10: =IF(Asistencia!H11="","",Asistencia!H11) | BN10: =IF(Asistencia!I11="","",Asistencia!I11) | BO10: =IF(Asistencia!J11="","",Asistencia!J11) | BP10: =IF(Asistencia!K11="","",Asistencia!K11) | BQ10: =IF(Asistencia!L11="","",Asistencia!L11)
A11: =IF(Y11="","",INDEX($AB$5:$AB$323,Y11)) | B11: =IF(Y11="","",INDEX($AD$5:$AD$323,Y11)) | E11: =IF($A11="","",_xlfn.TEXTJOIN(" / ",TRUE(),IF(SUMIFS($AP$5:$AP$323,$AA$5:$AA$323,$Z11,$AF$5:$AF$323,"ARMIDA")>0,IFERROR("ARMIDA-"&INDEX($AE$5:$AE$323,MATCH($Z11&"ARMIDA",$AA$5:$AA$323&$AF$5:$AF$323,0)),"ARMIDA"),""),IF(SUMIFS($AP$5:$AP$323,$AA$5:$AA$323,$Z11,$AF$5:$AF$323,"AURIGA")>0,IFERROR("AURIGA-"&INDEX($AE$5:$AE$323,MATCH($Z11&"AURIGA",$AA$5:$AA$323&$AF$5:$AF$323,0)),"AURIGA"),""),IF(SUMIFS($AP$5:$AP$323,$AA$5:$AA$323,$Z11,$AF$5:$AF$323,"AURORA")>0,IFERROR("AURORA-"&INDEX($AE$5:$AE$323,MATCH($Z11&"AURORA",$AA$5:$AA$323&$AF$5:$AF$323,0)),"AURORA"),""),IF(SUMIFS($AP$5:$AP$323,$AA$5:$AA$323,$Z11,$AF$5:$AF$323,"CITICA")>0,IFERROR("CITICA-"&INDEX($AE$5:$AE$323,MATCH($Z11&"CITICA",$AA$5:$AA$323&$AF$5:$AF$323,0)),"CITICA"),""),IF(SUMIFS($AP$5:$AP$323,$AA$5:$AA$323,$Z11,$AF$5:$AF$323,"GM")>0,IFERROR("GM-"&INDEX($AE$5:$AE$323,MATCH($Z11&"GM",$AA$5:$AA$323&$AF$5:$AF$323,0)),"GM"),""),IF(SUMIFS($AP$5:$AP$323,$AA$5:$AA$323,$Z11,$AF$5:$AF$323,"TORRE BALZAK")>0,IFERROR("TORRE BALZAK-"&INDEX($AE$5:$AE$323,MATCH($Z11&"TORRE BALZAK",$AA$5:$AA$323&$AF$5:$AF$323,0)),"TORRE BALZAK"),""),IF(SUMIFS($AP$5:$AP$323,$AA$5:$AA$323,$Z11,$AF$5:$AF$323,"TORRE OLMA")>0,IFERROR("TORRE OLMA-"&INDEX($AE$5:$AE$323,MATCH($Z11&"TORRE OLMA",$AA$5:$AA$323&$AF$5:$AF$323,0)),"TORRE OLMA"),""),IF(SUMIFS($AP$5:$AP$323,$AA$5:$AA$323,$Z11,$AF$5:$AF$323,"OTROS")>0,IFERROR("OTROS-"&INDEX($AE$5:$AE$323,MATCH($Z11&"OTROS",$AA$5:$AA$323&$AF$5:$AF$323,0)),"OTROS"),""))) | F11: =IF($A11="","",IFERROR(INDEX($BK$5:$BK$323,MATCH($Z11,$AA$5:$AA$323,0)),"-")) | G11: =IF($A11="","",IFERROR(INDEX($BL$5:$BL$323,MATCH($Z11,$AA$5:$AA$323,0)),"-")) | H11: =IF($A11="","",IFERROR(INDEX($BM$5:$BM$323,MATCH($Z11,$AA$5:$AA$323,0)),"-")) | I11: =IF($A11="","",IFERROR(INDEX($BN$5:$BN$323,MATCH($Z11,$AA$5:$AA$323,0)),"-")) | J11: =IF($A11="","",IFERROR(INDEX($BO$5:$BO$323,MATCH($Z11,$AA$5:$AA$323,0)),"-")) | K11: =IF($A11="","",IFERROR(INDEX($BP$5:$BP$323,MATCH($Z11,$AA$5:$AA$323,0)),"-")) | L11: =IF($A11="","",IFERROR(INDEX($BQ$5:$BQ$323,MATCH($Z11,$AA$5:$AA$323,0)),"-")) | M11: =IF($A11="","",(--(SUMIF($AA$5:$AA$323,$Z11,$AI$5:$AI$323)>0))+(--(SUMIF($AA$5:$AA$323,$Z11,$AJ$5:$AJ$323)>0))+(--(SUMIF($AA$5:$AA$323,$Z11,$AK$5:$AK$323)>0))+(--(SUMIF($AA$5:$AA$323,$Z11,$AL$5:$AL$323)>0))+(--(SUMIF($AA$5:$AA$323,$Z11,$AM$5:$AM$323)>0))+(--(SUMIF($AA$5:$AA$323,$Z11,$AN$5:$AN$323)>0))+(--(SUMIF($AA$5:$AA$323,$Z11,$AO$5:$AO$323)>0))) | N11: =IF($A11="","",MAX(0,M11-6)) | O11: =IF($A11="","",SUMIF($AA$5:$AA$323,$Z11,$AP$5:$AP$323)-M11) | P11: =IF($A11="","",SUMIF($AA$5:$AA$323,$Z11,$BG$5:$BG$323)) | Q11: =IF($A11="","",SUMIF($AA$5:$AA$323,$Z11,$BH$5:$BH$323)) | R11: =IF($A11="","",SUMIF($AA$5:$AA$323,$Z11,$BI$5:$BI$323)) | U11: =IF($A11="","",SUMIF($AA$5:$AA$323,$Z11,$BJ$5:$BJ$323)) | W11: =IF($A11="","",_xlfn.TEXTJOIN(" | ",TRUE(),IF(N11>0,"+ de 6 días: revisar adicionales",""),IF(O11>0,"Doble evento mismo día: revisar turno/pago",""),IF(SUMIF($AA$5:$AA$323,$Z11,$AX$5:$AX$323)>((--(SUMIF($AA$5:$AA$323,$Z11,$AQ$5:$AQ$323)>0))+(--(SUMIF($AA$5:$AA$323,$Z11,$AR$5:$AR$323)>0))+(--(SUMIF($AA$5:$AA$323,$Z11,$AS$5:$AS$323)>0))+(--(SUMIF($AA$5:$AA$323,$Z11,$AT$5:$AT$323)>0))+(--(SUMIF($AA$5:$AA$323,$Z11,$AU$5:$AU$323)>0))+(--(SUMIF($AA$5:$AA$323,$Z11,$AV$5:$AV$323)>0))+(--(SUMIF($AA$5:$AA$323,$Z11,$AW$5:$AW$323)>0))),"FL múltiple mismo día: revisar pago festivo",""),IF(SUMIF($AA$5:$AA$323,$Z11,$BF$5:$BF$323)>((--(SUMIF($AA$5:$AA$323,$Z11,$AY$5:$AY$323)>0))+(--(SUMIF($AA$5:$AA$323,$Z11,$AZ$5:$AZ$323)>0))+(--(SUMIF($AA$5:$AA$323,$Z11,$BA$5:$BA$323)>0))+(--(SUMIF($AA$5:$AA$323,$Z11,$BB$5:$BB$323)>0))+(--(SUMIF($AA$5:$AA$323,$Z11,$BC$5:$BC$323)>0))+(--(SUMIF($AA$5:$AA$323,$Z11,$BD$5:$BD$323)>0))+(--(SUMIF($AA$5:$AA$323,$Z11,$BE$5:$BE$323)>0))),"DL múltiple mismo día: revisar pago descanso",""))) | Y11: =IFERROR(MATCH(7,$AH$5:$AH$323,0),"") | Z11: =IF(Y11="","",INDEX($AA$5:$AA$323,Y11)) | AA11: =IF(AC11="","","M:"&AC11) | AB11: =IF(Asistencia!A12="","",Asistencia!A12) | AC11: =IF(Asistencia!A12="","",SUBSTITUTE(SUBSTITUTE(SUBSTITUTE(SUBSTITUTE(SUBSTITUTE(SUBSTITUTE(SUBSTITUTE(UPPER(TRIM(Asistencia!A12)),"Á","A"),"É","E"),"Í","I"),"Ó","O"),"Ú","U"),"Ñ","N")," "," ")) | AD11: =IF(Asistencia!E12="","",Asistencia!E12) | AE11: =IF(Asistencia!D12="","",UPPER(TRIM(Asistencia!D12))) | AF11: ARMIDA | AG11: =IF(AND(AA11<>"",COUNTIF($AA$5:AA11,AA11)=1),1,0) -> 0 | AH11: =IF(AG11=1,SUM($AG$5:AG11),"") | AI11: =IF(OR(EXACT(Asistencia!F12,"A"),EXACT(Asistencia!F12,"R"),EXACT(Asistencia!F12,"DL"),EXACT(Asistencia!F12,"FL"),EXACT(Asistencia!F12,"FE"),EXACT(Asistencia!F12,"PCS"),EXACT(Asistencia!F12,"V")),1,0) -> 0 | AJ11: =IF(OR(EXACT(Asistencia!G12,"A"),EXACT(Asistencia!G12,"R"),EXACT(Asistencia!G12,"DL"),EXACT(Asistencia!G12,"FL"),EXACT(Asistencia!G12,"FE"),EXACT(Asistencia!G12,"PCS"),EXACT(Asistencia!G12,"V")),1,0) -> 0 | AK11: =IF(OR(EXACT(Asistencia!H12,"A"),EXACT(Asistencia!H12,"R"),EXACT(Asistencia!H12,"DL"),EXACT(Asistencia!H12,"FL"),EXACT(Asistencia!H12,"FE"),EXACT(Asistencia!H12,"PCS"),EXACT(Asistencia!H12,"V")),1,0) -> 0 | AL11: =IF(OR(EXACT(Asistencia!I12,"A"),EXACT(Asistencia!I12,"R"),EXACT(Asistencia!I12,"DL"),EXACT(Asistencia!I12,"FL"),EXACT(Asistencia!I12,"FE"),EXACT(Asistencia!I12,"PCS"),EXACT(Asistencia!I12,"V")),1,0) -> 0 | AM11: =IF(OR(EXACT(Asistencia!J12,"A"),EXACT(Asistencia!J12,"R"),EXACT(Asistencia!J12,"DL"),EXACT(Asistencia!J12,"FL"),EXACT(Asistencia!J12,"FE"),EXACT(Asistencia!J12,"PCS"),EXACT(Asistencia!J12,"V")),1,0) -> 0 | AN11: =IF(OR(EXACT(Asistencia!K12,"A"),EXACT(Asistencia!K12,"R"),EXACT(Asistencia!K12,"DL"),EXACT(Asistencia!K12,"FL"),EXACT(Asistencia!K12,"FE"),EXACT(Asistencia!K12,"PCS"),EXACT(Asistencia!K12,"V")),1,0) -> 0 | AO11: =IF(OR(EXACT(Asistencia!L12,"A"),EXACT(Asistencia!L12,"R"),EXACT(Asistencia!L12,"DL"),EXACT(Asistencia!L12,"FL"),EXACT(Asistencia!L12,"FE"),EXACT(Asistencia!L12,"PCS"),EXACT(Asistencia!L12,"V")),1,0) -> 0 | AP11: =SUM(AI11:AO11) -> 0 | AQ11: =IF(EXACT(Asistencia!F12,"FL"),1,0) -> 0 | AR11: =IF(EXACT(Asistencia!G12,"FL"),1,0) -> 0 | AS11: =IF(EXACT(Asistencia!H12,"FL"),1,0) -> 0 | AT11: =IF(EXACT(Asistencia!I12,"FL"),1,0) -> 0 | AU11: =IF(EXACT(Asistencia!J12,"FL"),1,0) -> 0 | AV11: =IF(EXACT(Asistencia!K12,"FL"),1,0) -> 0 | AW11: =IF(EXACT(Asistencia!L12,"FL"),1,0) -> 0 | AX11: =SUM(AQ11:AW11) -> 0 | AY11: =IF(EXACT(Asistencia!F12,"DL"),1,0) -> 0 | AZ11: =IF(EXACT(Asistencia!G12,"DL"),1,0) -> 0 | BA11: =IF(EXACT(Asistencia!H12,"DL"),1,0) -> 0 | BB11: =IF(EXACT(Asistencia!I12,"DL"),1,0) -> 0 | BC11: =IF(EXACT(Asistencia!J12,"DL"),1,0) -> 0 | BD11: =IF(EXACT(Asistencia!K12,"DL"),1,0) -> 0 | BE11: =IF(EXACT(Asistencia!L12,"DL"),1,0) -> 0 | BF11: =SUM(AY11:BE11) -> 0 | BG11: =IF(ISNUMBER(Asistencia!M12),Asistencia!M12,0) -> 0 | BH11: =IF(ISNUMBER(Asistencia!N12),Asistencia!N12,0) -> 0 | BI11: =IF(ISNUMBER(Asistencia!O12),Asistencia!O12,0) -> 0 | BJ11: =IF(ISNUMBER(Asistencia!P12),Asistencia!P12,0) -> 0 | BK11: =IF(Asistencia!F12="","",Asistencia!F12) | BL11: =IF(Asistencia!G12="","",Asistencia!G12) | BM11: =IF(Asistencia!H12="","",Asistencia!H12) | BN11: =IF(Asistencia!I12="","",Asistencia!I12) | BO11: =IF(Asistencia!J12="","",Asistencia!J12) | BP11: =IF(Asistencia!K12="","",Asistencia!K12) | BQ11: =IF(Asistencia!L12="","",Asistencia!L12)
